{"schema_version":"glitch.crypto.binance-usdm-stream-evidence.v1","session_id":"ef8dc32d-fcff-4814-9419-b04573c2aaca","sequence":1,"recorded_utc":"2026-08-25T02:48:25.871Z","channel":"supervisor","kind":"transition","payload":{"action":"start","symbol":"BTCUSDT","private_enabled":false,"mutation_authority":false}}
{"schema_version":"glitch.crypto.binance-usdm-stream-evidence.v1","session_id":"ef8dc32d-fcff-4814-9419-b04573c2aaca","sequence":2,"recorded_utc":"2026-08-25T02:48:25.941Z","channel":"public-depth","kind":"transition","payload":{"state":"connecting","epoch":1,"stream":"btcusdt@depth@100ms","connection_id":"fc393e01-4a66-488a-8382-876f9e9544ec"}}
{"schema_version":"glitch.crypto.binance-usdm-stream-evidence.v1","session_id":"ef8dc32d-fcff-4814-9419-b04573c2aaca","sequence":3,"recorded_utc":"2026-08-25T02:48:27.941Z","channel":"public-depth","kind":"transition","payload":{"state":"synchronizing","epoch":1,"connection_id":"fc393e01-4a66-488a-8382-876f9e9544ec"}}
{"schema_version":"glitch.crypto.binance-usdm-stream-evidence.v2","session_id":"ef8dc32d-fcff-4814-9419-b04573c2aaca","sequence":4,"recorded_utc":"2026-08-25T02:48:28.049Z","channel":"public-depth","kind":"message","payload":{"e":"depthUpdate","E":1787626106569,"T":1787626106543,"s":"BTCUSDT","ps":"BTCUSDT","U":410738874254,"u":410738875461,"pu":410738872735,"b":[["76741.50","0.0000"],["80646.90","0.0052"],["80649.30","0.0000"]],"a":[],"st":1},"provenance":{"venue":"BINANCE_USDM","instrument":"BTCUSDT","channel":"public-depth","connection_id":"fc393e01-4a66-488a-8382-876f9e9544ec","local_receive_timestamp_ms":1787626108049,"monotonic_receive_ns":"2274256000","exchange_timestamp_ms":1787626106569,"provider_sequence":{"event_type":"depthUpdate","event_time_ms":1787626106569,"aggregate_trade_id":null,"first_trade_id":null,"last_trade_id":null,"trade_time_ms":null,"first_update_id":410738874254,"final_update_id":410738875461,"previous_final_update_id":410738872735,"transaction_time_ms":1787626106543},"normalization_version":"binance-usdm-depth-inspection.v1","raw_frame":"{\"e\":\"depthUpdate\",\"E\":1787626106569,\"T\":1787626106543,\"s\":\"BTCUSDT\",\"ps\":\"BTCUSDT\",\"U\":410738874254,\"u\":410738875461,\"pu\":410738872735,\"b\":[[\"76741.50\",\"0.0000\"],[\"80646.90\",\"0.0052\"],[\"80649.30\",\"0.0000\"]],\"a\":[],\"st\":1}","raw_frame_sha256":"6f5c4b55cec7e078337c38ec592c856dd1d99e46be7bd69bdbcda12cf9515caf"}}
{"schema_version":"glitch.crypto.binance-usdm-stream-evidence.v2","session_id":"ef8dc32d-fcff-4814-9419-b04573c2aaca","sequence":5,"recorded_utc":"2026-08-25T02:48:28.490Z","channel":"public-depth","kind":"message","payload":{"e":"depthUpdate","E":1787626106983,"T":1787626106939,"s":"BTCUSDT","ps":"BTCUSDT","U":410738878276,"u":410738878880,"pu":410738875461,"b":[["80164.20","0.0000"],["80770.90","0.0012"]],"a":[["96936.00","0.0000"]],"st":1},"provenance":{"venue":"BINANCE_USDM","instrument":"BTCUSDT","channel":"public-depth","connection_id":"fc393e01-4a66-488a-8382-876f9e9544ec","local_receive_timestamp_ms":1787626108490,"monotonic_receive_ns":"2715438900","exchange_timestamp_ms":1787626106983,"provider_sequence":{"event_type":"depthUpdate","event_time_ms":1787626106983,"aggregate_trade_id":null,"first_trade_id":null,"last_trade_id":null,"trade_time_ms":null,"first_update_id":410738878276,"final_update_id":410738878880,"previous_final_update_id":410738875461,"transaction_time_ms":1787626106939},"normalization_version":"binance-usdm-depth-inspection.v1","raw_frame":"{\"e\":\"depthUpdate\",\"E\":1787626106983,\"T\":1787626106939,\"s\":\"BTCUSDT\",\"ps\":\"BTCUSDT\",\"U\":410738878276,\"u\":410738878880,\"pu\":410738875461,\"b\":[[\"80164.20\",\"0.0000\"],[\"80770.90\",\"0.0012\"]],\"a\":[[\"96936.00\",\"0.0000\"]],\"st\":1}","raw_frame_sha256":"8089899ed7a77f094ebc03fc546ad4c2d8e584fbfcce8e4d2bcec65dc9c15fb8"}}
{"schema_version":"glitch.crypto.binance-usdm-stream-evidence.v2","session_id":"ef8dc32d-fcff-4814-9419-b04573c2aaca","sequence":6,"recorded_utc":"2026-08-25T02:48:28.607Z","channel":"public-depth","kind":"message","payload":{"e":"depthUpdate","E":1787626107129,"T":1787626106975,"s":"BTCUSDT","ps":"BTCUSDT","U":410738879231,"u":410738879231,"pu":410738878880,"b":[["80770.90","0.0000"]],"a":[],"st":1},"provenance":{"venue":"BINANCE_USDM","instrument":"BTCUSDT","channel":"public-depth","connection_id":"fc393e01-4a66-488a-8382-876f9e9544ec","local_receive_timestamp_ms":1787626108607,"monotonic_receive_ns":"2832734100","exchange_timestamp_ms":1787626107129,"provider_sequence":{"event_type":"depthUpdate","event_time_ms":1787626107129,"aggregate_trade_id":null,"first_trade_id":null,"last_trade_id":null,"trade_time_ms":null,"first_update_id":410738879231,"final_update_id":410738879231,"previous_final_update_id":410738878880,"transaction_time_ms":1787626106975},"normalization_version":"binance-usdm-depth-inspection.v1","raw_frame":"{\"e\":\"depthUpdate\",\"E\":1787626107129,\"T\":1787626106975,\"s\":\"BTCUSDT\",\"ps\":\"BTCUSDT\",\"U\":410738879231,\"u\":410738879231,\"pu\":410738878880,\"b\":[[\"80770.90\",\"0.0000\"]],\"a\":[],\"st\":1}","raw_frame_sha256":"ddb9e8b4980a669186ddc4bdad2da3542c2f04a41c127d8d9a17e606e13e23cc"}}
{"schema_version":"glitch.crypto.binance-usdm-stream-evidence.v2","session_id":"ef8dc32d-fcff-4814-9419-b04573c2aaca","sequence":7,"recorded_utc":"2026-08-25T02:48:28.744Z","channel":"public-depth","kind":"message","payload":{"e":"depthUpdate","E":1787626107267,"T":1787626107179,"s":"BTCUSDT","ps":"BTCUSDT","U":410738880776,"u":410738881154,"pu":410738879231,"b":[["80164.20","0.0049"],["80770.90","0.0025"]],"a":[],"st":1},"provenance":{"venue":"BINANCE_USDM","instrument":"BTCUSDT","channel":"public-depth","connection_id":"fc393e01-4a66-488a-8382-876f9e9544ec","local_receive_timestamp_ms":1787626108744,"monotonic_receive_ns":"2969725800","exchange_timestamp_ms":1787626107267,"provider_sequence":{"event_type":"depthUpdate","event_time_ms":1787626107267,"aggregate_trade_id":null,"first_trade_id":null,"last_trade_id":null,"trade_time_ms":null,"first_update_id":410738880776,"final_update_id":410738881154,"previous_final_update_id":410738879231,"transaction_time_ms":1787626107179},"normalization_version":"binance-usdm-depth-inspection.v1","raw_frame":"{\"e\":\"depthUpdate\",\"E\":1787626107267,\"T\":1787626107179,\"s\":\"BTCUSDT\",\"ps\":\"BTCUSDT\",\"U\":410738880776,\"u\":410738881154,\"pu\":410738879231,\"b\":[[\"80164.20\",\"0.0049\"],[\"80770.90\",\"0.0025\"]],\"a\":[],\"st\":1}","raw_frame_sha256":"6039589b7aaf2e7b54aff30384382f5f60d7bffe720491ad871dfd1547a1d384"}}
{"schema_version":"glitch.crypto.binance-usdm-stream-evidence.v2","session_id":"ef8dc32d-fcff-4814-9419-b04573c2aaca","sequence":8,"recorded_utc":"2026-08-25T02:48:28.930Z","channel":"public-depth","kind":"message","payload":{"e":"depthUpdate","E":1787626107441,"T":1787626107335,"s":"BTCUSDT","ps":"BTCUSDT","U":410738882199,"u":410738882447,"pu":410738881154,"b":[["80741.00","0.0000"],["80770.90","0.0000"]],"a":[],"st":1},"provenance":{"venue":"BINANCE_USDM","instrument":"BTCUSDT","channel":"public-depth","connection_id":"fc393e01-4a66-488a-8382-876f9e9544ec","local_receive_timestamp_ms":1787626108930,"monotonic_receive_ns":"3155495300","exchange_timestamp_ms":1787626107441,"provider_sequence":{"event_type":"depthUpdate","event_time_ms":1787626107441,"aggregate_trade_id":null,"first_trade_id":null,"last_trade_id":null,"trade_time_ms":null,"first_update_id":410738882199,"final_update_id":410738882447,"previous_final_update_id":410738881154,"transaction_time_ms":1787626107335},"normalization_version":"binance-usdm-depth-inspection.v1","raw_frame":"{\"e\":\"depthUpdate\",\"E\":1787626107441,\"T\":1787626107335,\"s\":\"BTCUSDT\",\"ps\":\"BTCUSDT\",\"U\":410738882199,\"u\":410738882447,\"pu\":410738881154,\"b\":[[\"80741.00\",\"0.0000\"],[\"80770.90\",\"0.0000\"]],\"a\":[],\"st\":1}","raw_frame_sha256":"9f96c9312e0862ce54645dce40a96ada126978be4141e5a187b92c703ae53119"}}
{"schema_version":"glitch.crypto.binance-usdm-stream-evidence.v2","session_id":"ef8dc32d-fcff-4814-9419-b04573c2aaca","sequence":9,"recorded_utc":"2026-08-25T02:48:29.048Z","channel":"public-depth","kind":"message","payload":{"e":"depthUpdate","E":1787626107568,"T":1787626107479,"s":"BTCUSDT","ps":"BTCUSDT","U":410738883468,"u":410738883727,"pu":410738882447,"b":[["60000.00","19.8024"],["60100.00","0.0059"],["80770.90","0.0020"]],"a":[],"st":1},"provenance":{"venue":"BINANCE_USDM","instrument":"BTCUSDT","channel":"public-depth","connection_id":"fc393e01-4a66-488a-8382-876f9e9544ec","local_receive_timestamp_ms":1787626109048,"monotonic_receive_ns":"3273655800","exchange_timestamp_ms":1787626107568,"provider_sequence":{"event_type":"depthUpdate","event_time_ms":1787626107568,"aggregate_trade_id":null,"first_trade_id":null,"last_trade_id":null,"trade_time_ms":null,"first_update_id":410738883468,"final_update_id":410738883727,"previous_final_update_id":410738882447,"transaction_time_ms":1787626107479},"normalization_version":"binance-usdm-depth-inspection.v1","raw_frame":"{\"e\":\"depthUpdate\",\"E\":1787626107568,\"T\":1787626107479,\"s\":\"BTCUSDT\",\"ps\":\"BTCUSDT\",\"U\":410738883468,\"u\":410738883727,\"pu\":410738882447,\"b\":[[\"60000.00\",\"19.8024\"],[\"60100.00\",\"0.0059\"],[\"80770.90\",\"0.0020\"]],\"a\":[],\"st\":1}","raw_frame_sha256":"5458983e78d5fe01fc61104994f5a267ad054c9df4a92019a67b89d1bb1c2c48"}}
{"schema_version":"glitch.crypto.binance-usdm-stream-evidence.v2","session_id":"ef8dc32d-fcff-4814-9419-b04573c2aaca","sequence":10,"recorded_utc":"2026-08-25T02:48:29.227Z","channel":"public-depth","kind":"message","payload":{"e":"depthUpdate","E":1787626107740,"T":1787626107645,"s":"BTCUSDT","ps":"BTCUSDT","U":410738885127,"u":410738885501,"pu":410738883727,"b":[["76732.30","32.2460"],["80646.90","0.0000"]],"a":[],"st":1},"provenance":{"venue":"BINANCE_USDM","instrument":"BTCUSDT","channel":"public-depth","connection_id":"fc393e01-4a66-488a-8382-876f9e9544ec","local_receive_timestamp_ms":1787626109227,"monotonic_receive_ns":"3452390000","exchange_timestamp_ms":1787626107740,"provider_sequence":{"event_type":"depthUpdate","event_time_ms":1787626107740,"aggregate_trade_id":null,"first_trade_id":null,"last_trade_id":null,"trade_time_ms":null,"first_update_id":410738885127,"final_update_id":410738885501,"previous_final_update_id":410738883727,"transaction_time_ms":1787626107645},"normalization_version":"binance-usdm-depth-inspection.v1","raw_frame":"{\"e\":\"depthUpdate\",\"E\":1787626107740,\"T\":1787626107645,\"s\":\"BTCUSDT\",\"ps\":\"BTCUSDT\",\"U\":410738885127,\"u\":410738885501,\"pu\":410738883727,\"b\":[[\"76732.30\",\"32.2460\"],[\"80646.90\",\"0.0000\"]],\"a\":[],\"st\":1}","raw_frame_sha256":"ac97d93ca0e53e9ee8137849be6cb0ba41e97ae7a23bc84752dfa3dae98d31e8"}}
{"schema_version":"glitch.crypto.binance-usdm-stream-evidence.v2","session_id":"ef8dc32d-fcff-4814-9419-b04573c2aaca","sequence":11,"recorded_utc":"2026-08-25T02:48:29.358Z","channel":"public-depth","kind":"message","payload":{"e":"depthUpdate","E":1787626107881,"T":1787626107838,"s":"BTCUSDT","ps":"BTCUSDT","U":410738886151,"u":410738887201,"pu":410738885501,"b":[["76732.30","32.2450"],["78751.60","0.0000"],["80647.90","0.0052"],["80770.00","27.6978"]],"a":[],"st":1},"provenance":{"venue":"BINANCE_USDM","instrument":"BTCUSDT","channel":"public-depth","connection_id":"fc393e01-4a66-488a-8382-876f9e9544ec","local_receive_timestamp_ms":1787626109358,"monotonic_receive_ns":"3583468400","exchange_timestamp_ms":1787626107881,"provider_sequence":{"event_type":"depthUpdate","event_time_ms":1787626107881,"aggregate_trade_id":null,"first_trade_id":null,"last_trade_id":null,"trade_time_ms":null,"first_update_id":410738886151,"final_update_id":410738887201,"previous_final_update_id":410738885501,"transaction_time_ms":1787626107838},"normalization_version":"binance-usdm-depth-inspection.v1","raw_frame":"{\"e\":\"depthUpdate\",\"E\":1787626107881,\"T\":1787626107838,\"s\":\"BTCUSDT\",\"ps\":\"BTCUSDT\",\"U\":410738886151,\"u\":410738887201,\"pu\":410738885501,\"b\":[[\"76732.30\",\"32.2450\"],[\"78751.60\",\"0.0000\"],[\"80647.90\",\"0.0052\"],[\"80770.00\",\"27.6978\"]],\"a\":[],\"st\":1}","raw_frame_sha256":"ff023d3e8bcbf3c0da8def5d074cb8cd48389136cdba2b12c2e558325c5a0799"}}
{"schema_version":"glitch.crypto.binance-usdm-stream-evidence.v2","session_id":"ef8dc32d-fcff-4814-9419-b04573c2aaca","sequence":12,"recorded_utc":"2026-08-25T02:48:29.521Z","channel":"public-depth","kind":"message","payload":{"e":"depthUpdate","E":1787626108043,"T":1787626107967,"s":"BTCUSDT","ps":"BTCUSDT","U":410738887880,"u":410738888230,"pu":410738887201,"b":[["63841.00","0.0000"],["64846.00","0.0000"],["80770.90","0.0040"]],"a":[],"st":1},"provenance":{"venue":"BINANCE_USDM","instrument":"BTCUSDT","channel":"public-depth","connection_id":"fc393e01-4a66-488a-8382-876f9e9544ec","local_receive_timestamp_ms":1787626109520,"monotonic_receive_ns":"3746128000","exchange_timestamp_ms":1787626108043,"provider_sequence":{"event_type":"depthUpdate","event_time_ms":1787626108043,"aggregate_trade_id":null,"first_trade_id":null,"last_trade_id":null,"trade_time_ms":null,"first_update_id":410738887880,"final_update_id":410738888230,"previous_final_update_id":410738887201,"transaction_time_ms":1787626107967},"normalization_version":"binance-usdm-depth-inspection.v1","raw_frame":"{\"e\":\"depthUpdate\",\"E\":1787626108043,\"T\":1787626107967,\"s\":\"BTCUSDT\",\"ps\":\"BTCUSDT\",\"U\":410738887880,\"u\":410738888230,\"pu\":410738887201,\"b\":[[\"63841.00\",\"0.0000\"],[\"64846.00\",\"0.0000\"],[\"80770.90\",\"0.0040\"]],\"a\":[],\"st\":1}","raw_frame_sha256":"bce781b09f1b665081552da0a3e0cb5983a2b4e31281fdf76f85c21dc40f8f7d"}}
{"schema_version":"glitch.crypto.binance-usdm-stream-evidence.v1","session_id":"ef8dc32d-fcff-4814-9419-b04573c2aaca","sequence":13,"recorded_utc":"2026-08-25T02:48:29.582Z","channel":"public-depth","kind":"snapshot","payload":{"lastUpdateId":410738888230,"bids":[["80770.90","0.0040"],["80770.00","27.6978"],["80769.90","0.0032"],["80769.00","0.0051"],["80766.30","0.0045"],["80766.00","0.0026"],["80764.60","0.0013"],["80762.30","0.0075"],["80762.20","0.0037"],["80761.40","0.0073"],["80761.20","0.0015"],["80760.30","0.0024"],["80760.20","0.0019"],["80760.00","0.0009"],["80759.40","281.3657"],["80759.20","0.0025"],["80759.10","43.9182"],["80759.00","43.2444"],["80758.80","43.3173"],["80758.40","43.1557"],["80758.30","0.0091"],["80758.10","0.0007"],["80758.00","0.0027"],["80757.70","43.8344"],["80757.50","43.6622"],["80756.90","43.4367"],["80756.80","43.7907"],["80756.30","43.9566"],["80755.80","43.9608"],["80755.70","0.0015"],["80755.30","0.0007"],["80755.20","0.0015"],["80755.00","43.1872"],["80754.90","0.0010"],["80754.80","0.0049"],["80754.70","43.4798"],["80754.50","43.9411"],["80754.40","0.0017"],["80754.20","0.0028"],["80753.90","43.6315"],["80753.40","0.0024"],["80753.10","43.6589"],["80752.70","0.0016"],["80752.60","0.0035"],["80752.40","43.6768"],["80751.80","43.7883"],["80751.30","627.6827"],["80751.20","6.6065"],["80750.80","6.6439"],["80750.00","50.5137"],["80749.60","13.1450"],["80749.10","6.6551"],["80749.00","0.0017"],["80748.80","186.0360"],["80748.00","6.5471"],["80747.50","6.6305"],["80747.40","6.6430"],["80747.30","0.0010"],["80747.20","0.0040"],["80746.50","6.5740"],["80746.20","0.0008"],["80746.10","0.0018"],["80746.00","0.0021"],["80745.40","0.0007"],["80745.00","6.5587"],["80744.90","6.5506"],["80743.80","624.2945"],["80743.70","26.9709"],["80743.40","6.5617"],["80742.90","13.5578"],["80742.80","6.6272"],["80742.70","6.6186"],["80742.30","6.6484"],["80742.20","43.3064"],["80742.10","13.3858"],["80741.80","13.5630"],["80741.40","6.6318"],["80741.30","0.0028"],["80741.20","43.7658"],["80741.10","13.5582"],["80740.50","13.4757"],["80740.10","0.0026"],["80739.70","20.1488"],["80739.40","0.0015"],["80739.10","13.4524"],["80738.90","6.6072"],["80738.40","13.5525"],["80738.20","13.6017"],["80738.10","13.6278"],["80737.50","13.5790"],["80737.40","13.4622"],["80737.20","0.0018"],["80737.10","249.8336"],["80736.40","13.4689"],["80736.10","6.5975"],["80736.00","13.6176"],["80735.60","0.0065"],["80735.10","0.0013"],["80735.00","0.0032"],["80734.50","13.3636"],["80734.10","0.0034"],["80734.00","0.0016"],["80733.70","0.0020"],["80733.60","0.0013"],["80733.50","13.4847"],["80733.20","13.4077"],["80732.70","0.0007"],["80732.60","0.0019"],["80729.90","13.6322"],["80706.70","0.0010"],["80704.20","0.3899"],["80700.00","0.0309"],["80681.50","0.0052"],["80679.00","0.0067"],["80677.00","0.0007"],["80674.70","0.0050"],["80659.20","0.0484"],["80647.90","0.0052"],["80636.20","0.0007"],["80624.80","0.0400"],["80617.60","0.0068"],["80600.00","0.0619"],["80583.90","0.0068"],["80580.00","0.0342"],["80553.30","0.0050"],["80544.00","0.0009"],["80543.00","0.0012"],["80524.90","0.0018"],["80503.00","0.0049"],["80500.00","11.1214"],["80479.60","0.0036"],["80444.30","0.0018"],["80434.70","0.0020"],["80431.90","0.0050"],["80429.70","0.0032"],["80410.30","10.6794"],["80393.50","0.0007"],["80375.00","0.0068"],["80351.20","0.0010"],["80310.60","0.0050"],["80302.20","0.0049"],["80300.00","0.0259"],["80219.50","0.0012"],["80201.00","0.0030"],["80200.00","0.0040"],["80189.20","0.0050"],["80164.20","0.0049"],["80150.90","0.0007"],["80126.90","0.0494"],["80102.70","3.1055"],["80102.00","0.0049"],["80067.80","0.0050"],["80017.40","0.0012"],["80000.00","3.9248"],["79946.40","0.0050"],["79934.70","0.0040"],["79902.20","0.0049"],["79898.20","9.5691"],["79896.10","0.0012"],["79888.00","2.3792"],["79825.10","0.0050"],["79800.00","96.1996"],["79745.20","554.1192"],["79745.00","126.4994"],["79744.90","316.4251"],["79744.30","0.0009"],["79744.10","0.0014"],["79744.00","631.5014"],["79743.90","633.8944"],["79743.80","0.0044"],["79743.20","0.0035"],["79742.90","0.0012"],["79742.60","0.0007"],["79742.40","0.0013"],["79742.30","0.0111"],["79742.20","0.0100"],["79741.50","0.0045"],["79740.20","0.0032"],["79740.10","0.0009"],["79737.50","0.0020"],["79736.50","0.0018"],["79736.20","0.0031"],["79736.10","0.0034"],["79736.00","633.6915"],["79735.90","0.0066"],["79734.90","633.6155"],["79734.80","0.0009"],["79734.00","0.0013"],["79733.80","635.2581"],["79732.70","0.0012"],["79732.60","0.0023"],["79730.40","0.0029"],["79730.30","1393.2841"],["79726.40","0.0037"],["79720.30","0.0053"],["79720.20","0.0066"],["79720.10","0.0020"],["79720.00","126.2973"],["79718.90","0.0067"],["79718.80","0.0075"],["79714.30","0.0013"],["79714.20","0.0012"],["79710.10","635.2058"],["79710.00","0.0277"],["79703.70","0.0050"],["79703.60","0.0066"],["79703.00","0.0049"],["79700.00","0.0313"],["79699.50","0.0015"],["79665.60","0.0007"],["79647.30","0.0100"],["79640.40","592.0534"],["79640.30","0.0045"],["79640.20","120.1450"],["79639.60","60.5306"],["79639.20","59.9999"],["79638.40","59.6212"],["79635.40","60.4019"],["79630.80","59.4890"],["79629.60","60.5502"],["79627.80","59.5062"],["79626.80","59.9860"],["79620.00","0.0023"],["79617.90","0.0007"],["79614.00","23.4209"],["79613.40","0.0034"],["79601.00","0.0030"],["79600.00","0.0040"],["79582.30","0.0050"],["79576.30","0.0359"],["79576.00","0.9980"],["79572.60","0.0012"],["79551.00","37.2401"],["79550.80","0.0021"],["79550.30","126.6932"],["79550.20","220.7708"],["79550.10","0.0061"],["79550.00","0.0084"],["79549.80","31.2587"],["79549.60","95.2357"],["79549.50","31.5400"],["79548.60","31.2539"],["79548.20","0.0022"],["79548.00","31.4418"],["79547.10","62.3787"],["79546.60","0.0023"],["79546.20","0.0055"],["79546.00","0.0017"],["79545.70","0.0046"],["79545.50","0.0050"],["79545.40","0.0009"],["79545.10","63.0056"],["79544.50","0.0030"],["79544.40","0.0016"],["79543.90","31.5951"],["79543.80","0.0022"],["79543.40","0.0074"],["79543.30","634.9391"],["79543.20","0.0075"],["79542.10","0.0018"],["79542.00","569.8603"],["79541.00","0.0034"],["79540.40","0.0009"],["79539.50","0.0007"],["79539.40","0.0025"],["79537.30","0.0064"],["79537.20","0.0025"],["79536.20","0.0047"],["79535.50","0.0026"],["79535.30","0.0008"],["79535.20","0.0009"],["79533.70","0.0010"],["79532.50","0.0025"],["79532.40","0.0024"],["79530.70","634.3040"],["79530.60","0.0039"],["79529.60","0.0031"],["79526.50","0.0047"],["79526.40","635.2264"],["79526.30","0.0031"],["79526.20","53.6224"],["79525.70","0.0055"],["79525.40","54.2636"],["79525.30","108.0386"],["79525.20","0.0012"],["79525.00","54.2859"],["79524.90","53.4829"],["79524.60","54.2815"],["79523.70","108.0791"],["79523.00","0.0007"],["79522.70","0.0015"],["79522.60","0.0029"],["79522.40","53.4948"],["79521.60","53.9594"],["79520.00","0.0030"],["79519.90","636.0460"],["79519.40","0.0013"],["79518.80","53.5771"],["79518.50","54.0756"],["79518.40","0.0040"],["79517.50","54.3990"],["79517.30","0.0032"],["79517.20","53.6342"],["79517.10","254.8241"],["79517.00","0.0042"],["79516.80","53.4443"],["79516.70","53.7561"],["79516.30","54.1433"],["79515.90","54.1560"],["79515.80","53.6843"],["79515.20","0.0029"],["79514.50","0.0012"],["79512.90","0.0045"],["79511.70","635.2574"],["79511.60","41.3786"],["79511.20","0.0017"],["79511.00","0.0014"],["79510.60","0.0300"],["79510.00","0.0037"],["79509.80","41.0872"],["79509.70","40.9332"],["79509.10","41.0914"],["79509.00","41.3700"],["79508.60","41.0818"],["79508.50","40.7928"],["79508.30","41.0854"],["79508.00","0.0007"],["79507.80","41.4908"],["79507.70","0.0007"],["79507.20","40.9572"],["79507.00","81.7294"],["79506.50","673.7272"],["79506.40","41.0401"],["79506.00","41.1031"],["79505.60","0.0009"],["79505.30","29.3693"],["79505.00","29.6824"],["79504.50","29.3329"],["79504.20","0.0049"],["79503.90","59.1540"],["79503.60","59.3362"],["79503.00","29.2354"],["79502.80","29.7543"],["79502.10","29.5310"],["79502.00","29.6890"],["79501.30","29.2579"],["79501.20","59.1757"],["79500.90","0.0032"],["79500.30","0.0023"],["79500.00","0.9591"],["79498.00","29.5061"],["79497.20","29.5314"],["79497.10","0.0007"],["79495.70","29.3752"],["79495.30","29.7892"],["79495.20","29.5212"],["79494.20","0.0048"],["79493.20","29.7073"],["79493.00","0.0020"],["79490.90","0.0010"],["79487.90","0.0015"],["79482.60","0.0009"],["79482.50","0.0012"],["79478.00","0.0126"],["79461.60","0.0036"],["79461.10","0.1573"],["79460.90","0.0050"],["79459.20","0.0045"],["79452.50","0.0054"],["79423.00","0.0007"],["79406.40","0.0034"],["79404.70","0.0160"],["79404.00","0.1036"],["79401.00","0.0030"],["79400.00","0.0040"],["79398.60","0.0024"],["79375.40","0.0007"],["79373.90","0.0054"],["79330.90","0.0831"],["79330.20","0.0255"],["79321.20","0.0013"],["79310.70","0.0020"],["79305.90","0.0049"],["79299.00","0.0068"],["79280.50","0.0020"],["79280.00","0.0023"],["79263.10","0.0535"],["79261.00","0.0025"],["79249.10","0.0012"],["79236.40","0.0164"],["79219.60","0.0066"],["79212.70","0.0034"],["79212.50","0.1600"],["79208.40","0.0007"],["79200.00","0.0040"],["79180.40","0.0007"],["79167.40","0.0054"],["79162.10","0.0100"],["79160.30","0.0009"],["79146.30","0.0379"],["79144.40","0.0013"],["79134.30","0.0034"],["79132.90","0.0007"],["79108.20","0.0049"],["79107.00","1.0000"],["79095.60","0.0020"],["79071.40","0.0020"],["79066.40","0.0009"],["79019.40","0.0012"],["79000.00","12.9551"],["78991.40","0.0050"],["78988.90","0.0050"],["78985.70","24.3209"],["78977.60","0.0036"],["78957.60","14.0439"],["78956.50","50.7829"],["78956.20","51.3542"],["78955.50","102.1387"],["78955.40","51.4701"],["78954.50","115.2058"],["78953.90","51.1733"],["78953.30","50.7759"],["78952.10","102.0271"],["78950.00","0.1582"],["78940.00","0.0023"],["78937.70","0.0007"],["78936.60","0.0045"],["78934.70","0.0080"],["78928.50","0.0034"],["78919.60","0.0160"],["78915.10","0.0033"],["78910.90","0.0049"],["78909.10","0.0007"],["78903.80","0.0045"],["78902.80","0.1267"],["78890.40","0.0007"],["78885.60","0.0012"],["78876.50","0.0007"],["78859.20","0.0484"],["78850.00","0.0316"],["78845.50","0.0257"],["78844.90","0.0100"],["78840.60","0.6341"],["78831.40","34.1352"],["78831.00","38.6686"],["78830.60","44.8040"],["78830.20","44.6042"],["78830.10","0.0102"],["78830.00","0.0042"],["78829.70","89.5730"],["78829.30","45.1555"],["78825.90","37.9507"],["78823.60","38.2491"],["78823.50","38.0290"],["78823.10","38.5181"],["78822.90","37.9039"],["78822.80","37.8689"],["78821.50","38.4128"],["78821.40","37.8741"],["78820.90","37.8641"],["78820.80","0.0018"],["78819.90","38.3059"],["78819.20","0.0016"],["78817.60","63.9758"],["78814.80","63.9193"],["78814.10","63.8823"],["78812.70","64.4647"],["78806.00","0.0008"],["78804.70","0.0011"],["78804.50","0.0016"],["78802.40","63.9253"],["78802.30","63.5051"],["78801.90","64.6482"],["78801.00","63.6711"],["78800.10","0.0026"],["78800.00","1.0452"],["78799.70","64.4216"],["78798.60","129.0699"],["78798.40","64.6111"],["78797.00","64.7025"],["78796.80","64.1203"],["78783.00","0.0048"],["78781.80","0.0020"],["78777.10","0.0012"],["78774.10","0.0040"],["78750.00","0.0200"],["78741.00","0.0020"],["78735.60","0.0066"],["78729.10","274.2328"],["78728.00","0.0008"],["78726.40","0.0078"],["78726.30","642.2922"],["78726.10","0.0021"],["78726.00","0.0054"],["78725.50","0.0114"],["78725.40","385.7587"],["78725.30","1279.9839"],["78725.10","0.0034"],["78724.70","116.2674"],["78724.50","58.0878"],["78724.20","319.5926"],["78723.90","0.0055"],["78723.70","0.0037"],["78723.40","0.0055"],["78722.80","0.0007"],["78722.40","642.0948"],["78721.00","643.3497"],["78720.40","0.0089"],["78720.30","0.0015"],["78720.00","0.0013"],["78719.60","256.2256"],["78719.50","640.8012"],["78718.00","0.0046"],["78717.90","0.0074"],["78717.80","0.0077"],["78717.60","385.4380"],["78715.10","0.0034"],["78714.50","642.5397"],["78714.40","0.0024"],["78714.10","0.0007"],["78713.90","58.1619"],["78713.70","0.0014"],["78713.50","0.0039"],["78713.40","640.4353"],["78713.30","57.0294"],["78713.20","0.0016"],["78713.00","0.0082"],["78712.60","57.8489"],["78712.40","57.6444"],["78711.60","57.0381"],["78710.90","57.5687"],["78710.40","0.0030"],["78710.30","0.0080"],["78710.10","0.0015"],["78709.40","57.6273"],["78709.30","57.6281"],["78709.20","0.0024"],["78709.00","0.0026"],["78708.90","57.2873"],["78708.30","57.1876"],["78708.10","57.8598"],["78707.80","0.0021"],["78707.10","0.0045"],["78707.00","1280.2970"],["78706.90","38.1935"],["78706.60","75.3977"],["78706.50","76.1341"],["78706.40","114.7402"],["78706.30","38.2218"],["78706.20","95.4968"],["78706.10","95.2762"],["78705.90","57.3316"],["78705.70","0.0034"],["78705.60","96.1664"],["78704.90","95.5062"],["78704.40","0.0052"],["78704.10","38.1404"],["78704.00","37.9271"],["78703.60","95.6769"],["78703.00","0.0072"],["78702.90","0.0014"],["78702.70","37.5848"],["78702.60","0.0027"],["78702.10","38.2054"],["78701.40","0.0009"],["78700.90","0.0010"],["78700.80","0.0034"],["78700.00","0.0320"],["78697.90","57.8184"],["78695.10","0.0007"],["78695.00","0.0176"],["78694.50","1.8762"],["78689.60","0.1642"],["78688.10","60.5560"],["78688.00","64.0177"],["78687.90","50.6782"],["78687.70","64.3997"],["78687.60","193.4812"],["78687.50","115.7012"],["78687.40","128.1708"],["78687.30","166.9813"],["78687.20","642.3668"],["78687.10","642.4591"],["78687.00","0.0083"],["78685.70","58.1876"],["78685.60","58.6997"],["78685.50","113.0922"],["78685.40","58.2428"],["78685.30","112.5735"],["78685.20","117.6800"],["78685.10","54.0435"],["78684.90","54.1711"],["78684.80","160.8208"],["78684.60","53.4717"],["78683.50","50.8007"],["78682.70","0.0013"],["78682.60","0.0092"],["78682.40","51.2178"],["78682.20","0.0036"],["78681.90","0.0055"],["78681.70","51.1988"],["78681.40","63.8640"],["78681.30","64.3116"],["78680.60","0.0077"],["78678.00","0.0088"],["78677.90","578.5674"],["78677.00","0.0100"],["78671.40","0.0100"],["78661.90","0.0013"],["78659.20","0.0484"],["78657.40","0.0023"],["78650.00","0.0080"],["78649.50","0.0179"],["78649.40","33.9779"],["78649.30","33.4414"],["78649.20","54.1034"],["78648.90","26.8517"],["78647.70","0.0283"],["78647.10","120.4499"],["78646.60","120.9846"],["78645.80","60.8460"],["78645.40","0.0007"],["78645.20","0.0053"],["78644.80","37.7063"],["78641.50","0.0094"],["78641.40","0.0021"],["78641.10","640.3911"],["78639.90","0.0038"],["78636.80","0.0024"],["78636.30","0.0013"],["78636.20","0.0066"],["78633.00","0.0025"],["78632.90","448.8302"],["78631.70","0.0020"],["78630.00","0.0013"],["78629.70","643.5722"],["78629.60","0.0093"],["78629.50","0.0525"],["78627.10","0.0027"],["78625.80","0.0013"],["78625.30","0.0039"],["78625.20","256.8078"],["78623.10","0.0012"],["78616.00","641.5804"],["78615.90","0.0060"],["78609.90","0.0020"],["78609.80","0.0007"],["78607.40","0.0050"],["78607.30","0.0032"],["78607.20","0.0052"],["78607.10","639.7669"],["78606.40","0.0047"],["78603.50","0.0007"],["78603.40","0.0051"],["78600.00","0.0380"],["78598.90","20.7910"],["78598.80","21.1039"],["78598.30","192.1779"],["78598.20","0.0044"],["78597.90","57.2577"],["78597.80","64.8445"],["78597.60","64.6630"],["78597.50","63.6315"],["78597.40","64.6741"],["78597.20","64.1300"],["78597.10","64.3836"],["78597.00","63.8218"],["78596.80","64.6329"],["78596.60","64.2025"],["78596.50","0.0097"],["78596.30","128.9093"],["78596.20","385.6801"],["78596.10","193.8376"],["78596.00","0.0014"],["78595.90","258.0706"],["78595.30","0.0076"],["78595.20","0.0008"],["78595.10","0.0021"],["78594.40","0.0034"],["78593.80","0.0021"],["78593.70","0.0066"],["78593.50","0.0012"],["78592.80","0.0015"],["78592.00","0.0008"],["78591.90","0.0020"],["78591.00","0.0046"],["78589.30","0.0023"],["78588.10","0.0022"],["78588.00","0.0017"],["78587.90","644.0474"],["78587.80","0.0040"],["78585.10","0.0065"],["78585.00","0.0016"],["78582.60","0.0008"],["78582.30","0.0020"],["78581.50","0.0021"],["78581.30","0.0007"],["78580.20","0.0032"],["78571.70","639.5392"],["78551.10","0.0015"],["78547.00","0.0588"],["78540.10","249.9589"],["78540.00","0.0104"],["78539.90","645.4447"],["78539.60","56.8643"],["78539.50","6.2434"],["78539.40","0.0007"],["78539.10","0.0028"],["78538.10","56.4947"],["78537.90","114.2127"],["78537.00","0.0023"],["78536.80","0.0010"],["78536.70","0.0032"],["78536.30","57.0248"],["78536.00","0.0017"],["78535.90","56.9734"],["78535.80","0.0057"],["78535.70","0.0087"],["78535.50","113.2347"],["78535.30","57.1589"],["78535.20","56.5190"],["78535.00","0.0063"],["78534.50","506.0523"],["78534.00","57.4432"],["78533.80","56.7420"],["78533.40","57.4247"],["78532.90","114.3469"],["78532.60","57.1857"],["78532.30","56.8847"],["78531.10","56.5498"],["78530.00","17.4089"],["78529.10","57.0520"],["78522.80","0.6367"],["78521.40","0.0029"],["78521.00","0.8278"],["78518.00","3.1839"],["78517.40","0.0010"],["78517.20","64.3735"],["78516.90","0.0010"],["78516.80","0.0019"],["78516.60","64.4100"],["78516.00","0.0043"],["78515.60","129.7675"],["78515.50","64.8299"],["78515.30","0.0026"],["78515.10","128.0831"],["78514.90","0.0017"],["78514.80","0.0009"],["78514.70","0.0047"],["78514.60","0.0037"],["78514.50","0.0010"],["78514.30","0.0064"],["78513.80","0.0019"],["78513.50","0.0058"],["78513.40","64.1746"],["78513.30","64.6114"],["78512.50","63.9310"],["78512.30","0.0017"],["78512.20","64.0814"],["78512.10","64.1386"],["78511.90","0.0008"],["78511.70","64.1173"],["78511.60","64.2284"],["78511.20","0.0014"],["78511.00","0.0551"],["78510.90","63.9489"],["78510.10","64.2871"],["78510.00","0.0014"],["78509.60","64.7274"],["78509.20","64.6085"],["78509.00","0.0010"],["78508.80","128.0949"],["78508.70","0.0047"],["78508.40","0.0021"],["78508.00","321.3480"],["78507.70","63.8865"],["78506.90","129.0670"],["78506.80","0.0015"],["78506.20","0.0009"],["78506.00","0.0016"],["78505.90","0.0027"],["78505.70","0.0026"],["78505.40","0.0012"],["78505.30","0.0048"],["78505.10","0.0042"],["78505.00","0.0320"],["78504.80","0.0024"],["78504.70","0.0008"],["78504.50","0.0054"],["78504.40","0.0009"],["78504.30","0.0026"],["78503.70","0.0060"],["78503.40","0.0018"],["78503.30","0.0036"],["78503.20","0.0035"],["78502.80","0.0007"],["78502.70","0.0014"],["78502.40","0.0042"],["78502.10","0.0017"],["78502.00","64.6007"],["78501.00","0.0059"],["78500.00","2.2146"],["78499.90","0.0009"],["78499.70","0.0025"],["78499.40","0.0013"],["78499.00","0.0031"],["78498.90","0.0251"],["78498.10","0.0021"],["78497.40","517.0636"],["78497.30","0.0007"],["78496.80","38.4968"],["78495.80","38.0567"],["78495.70","38.5971"],["78495.50","38.0941"],["78495.40","0.0009"],["78495.10","37.9729"],["78495.00","0.0031"],["78494.60","37.9116"],["78494.10","0.0008"],["78493.80","0.0016"],["78493.60","0.0036"],["78493.30","0.0054"],["78493.10","0.0020"],["78492.90","38.0844"],["78492.70","37.9902"],["78492.60","38.3950"],["78491.70","0.0009"],["78491.60","0.0019"],["78491.50","0.0029"],["78491.40","0.0024"],["78491.20","37.8780"],["78490.80","38.0002"],["78490.10","38.6173"],["78489.50","38.1330"],["78489.10","38.6159"],["78488.90","38.0584"],["78488.80","38.5161"],["78488.60","0.0027"],["78488.50","38.3323"],["78488.30","38.4475"],["78488.00","0.0032"],["78487.70","0.0009"],["78487.50","0.0008"],["78487.10","0.0012"],["78486.80","0.0020"],["78486.60","38.0406"],["78486.40","0.0007"],["78485.40","0.0009"],["78485.10","0.0028"],["78484.90","38.5936"],["78483.70","0.0026"],["78483.50","0.0042"],["78483.40","0.0014"],["78480.10","0.0017"],["78477.20","0.0010"],["78475.90","0.0021"],["78470.00","0.0716"],["78469.70","0.0009"],["78468.10","0.0018"],["78468.00","0.0032"],["78466.90","0.0037"],["78466.70","0.0007"],["78460.00","0.0007"],["78459.20","0.0484"],["78454.00","0.0500"],["78453.40","0.0007"],["78452.40","0.0007"],["78450.60","0.0034"],["78450.00","1.0923"],["78438.50","0.0010"],["78434.40","0.0160"],["78424.00","0.1721"],["78404.00","0.0500"],["78400.00","0.0260"],["78389.50","0.0050"],["78376.70","0.0028"],["78363.30","0.0245"],["78359.70","0.0010"],["78355.50","0.0165"],["78353.00","0.0100"],["78313.00","0.0650"],["78310.60","0.0007"],["78309.80","0.0045"],["78302.90","0.0510"],["78302.00","0.0120"],["78300.00","0.1600"],["78297.00","0.1995"],["78288.80","0.0221"],["78280.90","0.0010"],["78271.50","0.0013"],["78260.00","0.0023"],["78259.20","0.0484"],["78253.50","0.0034"],["78252.40","0.0100"],["78252.00","0.0100"],["78251.60","0.0066"],["78230.00","0.0007"],["78227.40","0.0022"],["78211.70","0.0054"],["78202.00","0.0860"],["78200.00","0.0098"],["78195.80","16.7080"],["78195.10","64.3038"],["78194.80","83.2771"],["78194.00","64.1122"],["78193.50","0.0030"],["78193.40","64.0408"],["78192.90","64.6013"],["78192.30","64.4306"],["78192.00","64.9423"],["78191.90","65.1903"],["78191.80","0.0100"],["78191.30","64.5177"],["78191.00","65.2417"],["78188.20","64.0902"],["78188.10","64.2881"],["78188.00","648.1770"],["78187.90","86.8702"],["78187.70","22.3175"],["78187.40","64.4850"],["78187.20","22.3144"],["78186.50","22.0047"],["78186.30","44.1632"],["78185.70","64.3259"],["78184.70","44.4205"],["78184.60","44.1776"],["78184.00","0.0012"],["78183.60","22.1124"],["78183.40","22.1361"],["78182.80","22.0867"],["78181.80","22.2673"],["78180.90","0.0030"],["78180.30","21.9023"],["78180.20","0.0007"],["78180.10","22.0994"],["78179.90","21.9367"],["78179.50","22.2772"],["78178.50","22.0390"],["78170.40","0.0008"],["78170.10","647.8658"],["78166.10","22.2585"],["78150.00","26.0127"],["78145.10","0.0042"],["78136.20","0.0010"],["78132.20","0.0035"],["78123.20","0.0010"],["78114.00","0.0029"],["78100.00","1.3154"],["78099.60","222.4138"],["78099.40","18.2977"],["78099.00","0.0015"],["78098.70","77.0294"],["78098.50","18.6077"],["78098.30","18.6150"],["78098.10","64.3325"],["78098.00","18.4435"],["78097.80","64.7083"],["78097.60","0.0020"],["78097.50","64.7098"],["78097.10","65.0902"],["78096.60","18.4444"],["78096.50","18.5022"],["78096.40","0.0011"],["78096.30","0.0025"],["78096.20","65.3150"],["78096.00","64.2256"],["78095.90","0.0008"],["78095.70","65.0488"],["78095.50","18.2696"],["78095.30","102.2200"],["78095.10","64.6123"],["78095.00","64.8343"],["78094.70","18.4277"],["78094.40","18.5974"],["78094.30","0.0014"],["78094.00","18.3225"],["78093.80","64.3564"],["78093.70","18.5164"],["78093.50","584.8642"],["78093.30","18.4265"],["78093.20","110.6451"],["78093.10","18.2742"],["78093.00","775.6112"],["78092.70","64.1979"],["78092.60","45.2706"],["78092.50","45.2497"],["78092.40","45.0170"],["78092.30","44.7684"],["78092.20","0.0015"],["78092.10","517.0951"],["78092.00","90.3768"],["78091.20","64.7529"],["78090.80","0.0017"],["78090.30","18.3981"],["78090.00","0.0082"],["78089.80","35.2970"],["78089.70","35.3677"],["78089.60","0.0014"],["78088.20","34.9605"],["78087.60","0.0015"]],"asks":[["80781.20","0.1251"],["80781.30","1.2344"],["80781.80","3.9310"],["80782.40","63.3104"],["80782.60","31.6552"],["80782.90","31.6552"],["80783.10","0.0042"],["80783.20","31.6552"],["80783.30","0.0014"],["80785.80","0.0008"],["80787.50","49.8150"],["80787.80","61.8731"],["80788.00","61.8731"],["80788.30","61.8731"],["80788.60","61.8731"],["80788.90","61.8731"],["80789.90","61.8731"],["80790.10","0.0007"],["80790.20","0.0027"],["80790.30","61.8731"],["80790.80","61.8731"],["80791.00","123.7462"],["80791.80","61.8731"],["80792.40","61.8731"],["80793.20","61.8731"],["80793.30","61.8731"],["80794.00","0.0059"],["80794.90","0.0007"],["80796.50","61.8731"],["80797.00","123.7462"],["80797.80","61.8731"],["80798.10","0.0010"],["80798.40","61.8731"],["80799.80","0.0015"],["80799.90","0.0055"],["80800.00","0.0636"],["80804.40","0.0020"],["80811.90","61.8731"],["80812.90","0.0024"],["80868.30","0.0010"],["80900.00","0.0306"],["80909.00","0.0065"],["80911.00","0.3000"],["80916.40","0.6170"],["80917.30","0.0050"],["80925.90","0.0007"],["80926.00","13.1979"],["80926.70","0.0010"],["80926.80","0.0028"],["80928.90","0.0034"],["80929.00","0.0031"],["80931.00","0.0020"],["80931.30","0.0020"],["80932.50","0.0015"],["80932.70","0.0033"],["80935.80","0.0011"],["80936.90","0.0028"],["80940.70","0.0064"],["80964.80","560.0575"],["80965.10","31.9738"],["80965.40","63.9476"],["80967.40","63.9476"],["80967.80","31.9738"],["80969.30","31.9738"],["80969.40","31.9738"],["80969.80","31.9738"],["80971.00","31.9738"],["80971.40","31.9738"],["80971.90","31.9738"],["80972.20","31.9738"],["80972.60","31.9738"],["80974.70","31.9738"],["80975.40","31.9738"],["80976.20","63.9476"],["80978.20","63.9476"],["80979.00","57.6587"],["80979.30","185.2710"],["80979.70","0.0024"],["80979.80","0.0010"],["80980.00","0.1316"],["80980.30","61.7578"],["80980.50","61.7570"],["80981.20","0.0015"],["80981.40","61.7570"],["80981.60","0.0008"],["80981.70","0.0124"],["80981.80","1236.0111"],["80982.00","0.0015"],["80982.30","0.0042"],["80983.10","33.2138"],["80983.50","0.0010"],["80983.60","0.0016"],["80983.80","61.7570"],["80984.00","0.0014"],["80984.70","0.0024"],["80985.70","0.0009"],["80986.20","61.7570"],["80986.30","33.2138"],["80986.50","61.7570"],["80987.00","0.0013"],["80987.10","0.0016"],["80987.30","0.0368"],["80987.60","61.7570"],["80987.90","0.0021"],["80988.60","0.0016"],["80988.70","0.0010"],["80989.10","618.0061"],["80989.20","0.0014"],["80989.70","0.0027"],["80989.80","618.0056"],["80990.00","0.0030"],["80990.10","0.0008"],["80991.10","0.0014"],["80991.80","0.0400"],["80992.60","0.0116"],["80997.50","0.0025"],["80997.90","0.0023"],["80998.10","618.0015"],["80999.70","0.0031"],["80999.90","1.1314"],["81000.00","34.9585"],["81000.40","2.0491"],["81001.90","618.0069"],["81002.00","0.0108"],["81002.10","52.4551"],["81002.60","52.4551"],["81003.00","52.4551"],["81004.10","0.0030"],["81004.20","52.4551"],["81004.90","0.0037"],["81005.50","52.4551"],["81006.10","52.4551"],["81006.20","157.3653"],["81006.40","52.4551"],["81006.70","52.4551"],["81007.80","52.4551"],["81008.40","52.4551"],["81008.90","52.4551"],["81009.50","0.3147"],["81010.10","0.0024"],["81010.50","52.4551"],["81012.40","0.0014"],["81012.80","0.0010"],["81019.00","0.0050"],["81025.30","0.0007"],["81025.40","0.0011"],["81029.00","0.0200"],["81035.60","1294.3208"],["81036.10","0.0012"],["81040.20","0.0007"],["81044.40","110.0645"],["81044.50","137.5984"],["81044.60","199.2931"],["81044.70","14.2010"],["81044.80","987.2253"],["81044.90","14.1931"],["81045.10","474.8897"],["81045.90","370.2113"],["81046.00","0.0074"],["81046.30","0.0069"],["81046.40","0.0010"],["81047.70","555.3063"],["81047.80","61.2714"],["81048.40","61.2692"],["81049.40","61.2692"],["81049.60","1234.0150"],["81049.70","1234.0347"],["81049.80","61.2692"],["81049.90","61.2692"],["81050.10","61.2692"],["81050.30","308.5074"],["81050.50","61.2692"],["81051.00","61.2692"],["81051.80","122.5391"],["81053.00","0.0031"],["81053.10","61.2723"],["81053.80","61.2692"],["81054.70","61.2692"],["81055.50","122.5384"],["81055.70","61.2692"],["81057.00","0.0069"],["81058.90","61.2692"],["81059.30","61.2692"],["81059.80","61.2692"],["81060.50","617.0042"],["81060.80","58.2553"],["81061.80","0.0014"],["81062.40","58.2326"],["81063.40","61.2692"],["81063.50","0.0033"],["81065.20","58.2326"],["81066.00","0.0023"],["81066.50","0.0033"],["81066.60","58.2473"],["81067.00","0.1009"],["81067.10","0.0010"],["81067.20","58.2326"],["81068.00","0.0016"],["81068.10","58.2326"],["81068.60","58.2326"],["81072.80","0.0007"],["81073.20","0.0023"],["81077.50","0.0045"],["81079.90","0.0010"],["81082.00","0.0009"],["81082.70","0.0024"],["81083.00","0.0008"],["81097.70","0.0301"],["81099.90","0.0120"],["81100.00","0.0010"],["81100.10","0.0012"],["81102.80","0.0032"],["81108.30","0.0049"],["81109.10","0.0045"],["81111.00","3.3657"],["81111.10","0.2000"],["81117.20","0.0020"],["81120.00","0.0061"],["81121.40","0.0007"],["81122.60","1.2318"],["81130.00","0.0008"],["81134.70","0.0100"],["81139.20","2.3416"],["81140.60","0.0045"],["81141.10","0.0084"],["81141.30","0.0091"],["81142.30","0.0045"],["81144.00","0.0046"],["81146.20","0.0025"],["81150.00","0.0018"],["81150.10","0.0017"],["81153.50","0.0020"],["81158.50","0.0028"],["81163.50","0.0007"],["81164.40","0.0008"],["81166.50","0.0184"],["81170.70","0.0009"],["81171.20","0.0026"],["81172.50","0.0030"],["81174.20","0.0037"],["81174.50","0.0041"],["81176.90","0.0020"],["81177.60","0.0029"],["81186.50","0.0010"],["81192.90","0.0015"],["81193.20","0.0015"],["81194.30","0.0033"],["81199.60","0.0015"],["81200.00","1.8274"],["81201.20","0.0015"],["81202.20","0.0160"],["81204.00","0.0010"],["81204.70","0.0013"],["81208.00","0.0007"],["81208.90","476.9358"],["81209.00","61.6549"],["81209.10","0.0110"],["81209.30","83.1961"],["81209.40","61.6000"],["81209.60","0.0015"],["81210.30","0.0047"],["81210.40","0.0107"],["81210.60","35.7846"],["81211.20","35.7846"],["81211.30","35.7846"],["81212.00","23.0337"],["81212.10","40.6558"],["81212.20","35.1388"],["81212.30","31.7417"],["81212.40","1267.1511"],["81212.60","25.0388"],["81212.90","42.0514"],["81213.00","60.8234"],["81214.10","35.1388"],["81214.20","31.7294"],["81214.30","25.0388"],["81215.10","0.0067"],["81215.20","647.7346"],["81215.80","31.7294"],["81216.10","0.0053"],["81216.20","35.1388"],["81216.80","0.0117"],["81216.90","123.2000"],["81217.30","0.0030"],["81217.50","0.0016"],["81217.60","0.0015"],["81220.00","0.6482"],["81221.60","0.0009"],["81223.60","0.0020"],["81225.50","0.0015"],["81226.70","25.8521"],["81226.80","1170.4114"],["81226.90","616.0339"],["81227.30","50.5638"],["81227.60","50.5638"],["81227.70","50.5638"],["81228.00","29.0746"],["81228.40","29.0746"],["81228.70","50.5638"],["81229.30","50.5638"],["81229.40","29.0746"],["81229.70","0.0010"],["81229.80","50.5638"],["81230.00","50.5638"],["81230.40","0.0015"],["81230.80","50.5638"],["81231.10","50.5638"],["81231.30","50.5638"],["81231.40","84.6272"],["81231.90","50.5638"],["81232.00","205.7400"],["81232.10","50.5638"],["81233.00","0.0015"],["81233.80","50.5638"],["81234.20","34.0634"],["81234.50","50.5638"],["81236.00","0.0014"],["81236.10","18.1192"],["81236.60","50.5638"],["81236.80","47.0162"],["81237.10","18.1811"],["81237.40","18.1811"],["81237.70","0.0630"],["81238.10","18.1811"],["81238.30","0.0630"],["81239.00","0.0630"],["81239.10","18.1811"],["81239.50","0.0630"],["81239.80","18.1811"],["81240.00","0.0015"],["81240.70","0.0833"],["81240.80","18.1811"],["81241.60","18.1811"],["81241.80","0.0630"],["81241.90","0.0630"],["81242.70","0.0630"],["81244.30","18.1811"],["81244.80","18.1811"],["81245.20","0.0630"],["81245.90","0.0630"],["81246.00","0.0630"],["81246.10","0.0630"],["81246.80","0.0015"],["81246.90","0.0630"],["81247.30","0.0015"],["81248.00","18.1811"],["81250.90","0.2221"],["81253.50","0.0015"],["81256.30","18.1811"],["81260.50","0.0010"],["81261.90","0.0105"],["81264.60","48.1500"],["81271.30","48.1500"],["81273.30","48.1500"],["81275.20","0.0076"],["81276.50","0.0148"],["81282.50","0.0011"],["81284.70","0.0020"],["81286.90","39.5760"],["81287.20","20.7541"],["81287.70","31.8398"],["81287.90","0.0019"],["81288.50","20.7541"],["81288.70","0.0040"],["81288.80","20.7541"],["81289.10","0.0170"],["81289.20","0.0078"],["81289.90","0.0090"],["81290.00","0.0082"],["81290.10","0.0027"],["81290.20","20.7541"],["81290.30","35.5869"],["81290.70","60.9044"],["81290.90","20.7541"],["81291.30","20.7541"],["81291.50","20.7583"],["81292.00","41.5082"],["81292.70","20.7541"],["81293.10","29.0619"],["81293.20","31.8424"],["81293.30","20.7541"],["81293.90","20.7541"],["81294.10","20.7541"],["81294.30","20.7541"],["81294.60","0.0033"],["81295.70","0.0023"],["81295.80","20.7541"],["81295.90","21.6009"],["81296.00","0.0030"],["81296.10","0.0068"],["81296.20","59.9566"],["81296.30","31.8398"],["81296.40","82.2541"],["81296.60","20.7541"],["81296.80","20.7541"],["81297.00","0.0035"],["81297.90","29.0619"],["81298.40","0.0041"],["81298.70","59.9566"],["81298.90","0.0014"],["81299.90","0.0174"],["81300.00","0.4533"],["81303.30","0.0068"],["81305.00","0.0070"],["81315.30","0.0007"],["81318.20","0.0058"],["81320.60","0.0015"],["81325.00","275.1264"],["81329.00","0.0015"],["81330.00","0.2798"],["81333.30","0.0040"],["81333.50","39.9675"],["81333.60","62.5241"],["81333.80","80.3208"],["81333.90","22.3637"],["81334.30","22.3637"],["81334.70","40.1604"],["81334.90","22.3637"],["81335.00","22.3637"],["81335.40","22.3637"],["81335.60","40.1604"],["81335.70","22.3637"],["81336.60","0.0060"],["81337.00","40.1604"],["81337.50","22.3637"],["81337.90","22.3637"],["81342.10","0.0568"],["81343.00","0.1474"],["81345.40","0.0032"],["81354.20","75.5665"],["81354.40","34.3786"],["81355.30","17.1893"],["81355.40","34.3786"],["81355.50","17.1893"],["81355.60","17.1893"],["81355.80","17.1893"],["81355.90","17.1893"],["81361.40","1.2290"],["81361.70","1.3827"],["81366.30","104.4919"],["81366.60","86.0830"],["81366.70","86.0830"],["81367.20","43.0415"],["81368.30","0.0014"],["81369.10","7.4082"],["81369.30","2.4734"],["81369.60","2.4734"],["81369.80","110.2657"],["81369.90","0.0019"],["81370.00","122.8915"],["81370.10","49.1575"],["81370.20","61.4608"],["81370.30","0.0134"],["81370.40","49.1590"],["81370.50","98.3150"],["81370.70","98.3150"],["81370.80","49.1575"],["81370.90","61.4439"],["81371.00","61.4439"],["81371.60","0.0061"],["81371.70","61.4439"],["81375.00","0.0070"],["81376.80","0.0052"],["81378.30","0.0018"],["81378.40","0.0040"],["81379.40","61.5000"],["81379.80","123.0000"],["81380.10","61.5000"],["81380.40","61.5000"],["81380.50","61.5000"],["81380.60","61.5000"],["81380.70","61.5000"],["81380.80","798.7639"],["81382.90","0.0015"],["81383.50","0.0060"],["81385.40","0.0031"],["81387.60","0.0015"],["81388.00","1.4590"],["81390.30","0.0012"],["81393.70","0.0030"],["81394.40","0.2455"],["81399.70","0.0086"],["81400.00","0.0010"],["81401.10","699.4052"],["81404.00","0.0015"],["81406.00","0.0069"],["81407.80","0.0015"],["81410.40","0.0015"],["81413.10","0.0015"],["81415.40","0.0015"],["81416.30","0.0041"],["81416.60","0.0015"],["81417.50","0.0015"],["81417.70","0.0015"],["81417.80","0.0015"],["81420.20","0.0123"],["81422.20","0.0030"],["81428.50","0.0117"],["81432.10","0.0030"],["81432.90","0.0517"],["81437.30","0.0134"],["81443.50","0.0030"],["81443.70","2.0000"],["81444.70","0.0151"],["81450.00","0.0098"],["81452.30","3.0692"],["81456.40","0.0030"],["81469.20","0.0050"],["81474.00","461.5275"],["81474.10","0.0020"],["81476.80","0.0045"],["81478.30","0.0030"],["81483.10","0.0025"],["81483.20","614.0070"],["81486.80","0.0007"],["81489.10","0.0078"],["81489.20","1228.0118"],["81491.10","0.0022"],["81491.20","0.0017"],["81491.70","0.5000"],["81496.40","614.0166"],["81496.50","614.0008"],["81499.90","0.0083"],["81500.00","640.9314"],["81500.10","0.0108"],["81500.50","614.0054"],["81501.00","0.0037"],["81505.20","0.0009"],["81507.30","0.0015"],["81507.90","0.0120"],["81508.50","614.0135"],["81512.30","0.0024"],["81519.20","0.0012"],["81520.00","0.0134"],["81524.50","0.0015"],["81540.60","0.0015"],["81541.20","0.0009"],["81544.10","836.8526"],["81544.80","0.0118"],["81544.90","0.0115"],["81546.10","0.0084"],["81546.20","552.6009"],["81546.30","1228.0105"],["81546.40","0.0059"],["81547.20","0.0047"],["81548.00","0.0060"],["81548.40","61.4000"],["81549.20","122.8000"],["81549.40","122.8000"],["81549.50","122.8000"],["81549.60","184.2000"],["81549.70","245.6000"],["81549.80","122.8000"],["81549.90","184.2025"],["81550.00","675.4123"],["81550.80","0.0082"],["81550.90","122.8144"],["81555.60","0.0030"],["81557.80","0.0007"],["81562.90","0.0051"],["81565.00","2.4512"],["81568.90","716.3440"],["81569.00","0.0037"],["81569.90","0.0114"],["81570.00","0.0357"],["81570.10","0.0071"],["81570.50","0.0015"],["81572.50","0.0015"],["81574.20","0.0015"],["81575.00","0.0015"],["81578.80","0.0030"],["81580.20","46.7301"],["81580.60","0.0015"],["81581.00","147.6090"],["81581.10","189.4347"],["81581.30","145.5565"],["81581.40","39.9315"],["81581.50","158.4171"],["81581.60","189.4347"],["81581.70","74.0539"],["81581.80","123.3234"],["81581.90","83.0536"],["81582.00","138.4404"],["81582.10","79.5206"],["81582.30","30.3246"],["81582.70","30.3246"],["81583.20","46.1245"],["81583.70","30.3246"],["81585.30","30.3246"],["81586.10","30.3246"],["81587.90","0.0032"],["81590.50","0.0015"],["81594.90","0.0015"],["81600.00","0.1838"],["81601.90","45.8381"],["81602.00","218.3235"],["81602.10","45.3680"],["81602.40","45.3680"],["81602.50","61.0937"],["81602.60","61.0937"],["81603.50","61.0937"],["81603.90","110.3230"],["81604.00","55.1615"],["81604.10","165.4860"],["81604.20","110.3279"],["81604.40","55.1642"],["81604.70","55.1615"],["81604.80","61.0937"],["81604.90","61.0937"],["81607.80","61.0937"],["81610.80","0.0130"],["81612.50","367.8091"],["81612.60","61.0962"],["81618.40","0.0030"],["81633.10","0.0085"],["81636.50","1.7721"],["81638.50","0.0068"],["81647.10","0.0079"],["81647.20","0.0080"],["81649.70","613.0102"],["81654.40","0.0015"],["81661.50","0.0452"],["81662.10","0.0015"],["81666.00","6.0000"],["81668.30","0.0015"],["81675.70","0.0015"],["81679.00","0.0010"],["81695.60","0.0015"],["81698.20","0.0192"],["81700.80","0.0026"],["81703.00","0.6119"],["81709.00","0.0070"],["81712.40","0.0030"],["81750.00","0.1223"],["81757.20","0.0015"],["81774.20","0.0080"],["81777.00","3.0570"],["81779.00","3.0570"],["81788.80","0.0015"],["81800.00","17.5221"],["81800.30","0.0007"],["81808.60","55.0533"],["81808.80","31.5953"],["81809.60","48.7891"],["81810.60","31.5953"],["81810.70","0.0025"],["81810.80","31.5953"],["81810.90","31.5953"],["81811.10","31.5953"],["81811.80","48.7998"],["81812.00","31.5953"],["81812.50","48.7998"],["81813.20","48.7998"],["81813.50","31.5953"],["81814.50","48.7998"],["81815.00","48.7998"],["81815.70","31.5953"],["81819.80","0.0045"],["81822.60","0.0032"],["81831.10","0.0500"],["81834.00","0.0183"],["81859.20","120.6794"],["81859.40","0.0067"],["81859.50","0.0057"],["81859.70","0.0024"],["81859.90","63.8297"],["81860.00","0.0102"],["81860.40","61.0746"],["81860.50","0.0010"],["81860.70","61.0769"],["81861.50","0.0022"],["81862.30","61.0746"],["81862.80","0.0025"],["81863.10","0.0017"],["81863.20","0.0063"],["81864.70","0.0022"],["81864.90","0.0022"],["81865.00","611.0061"],["81865.10","0.0216"],["81865.20","0.0115"],["81865.50","122.1492"],["81865.60","0.0053"],["81865.90","0.0152"],["81866.00","0.0165"],["81866.20","61.0746"],["81868.00","0.0060"],["81868.30","61.0746"],["81869.30","0.0025"],["81869.40","0.0107"],["81869.70","0.0046"],["81869.80","0.0009"],["81870.80","0.0062"],["81882.90","0.0010"],["81888.00","2.6105"],["81893.30","0.0015"],["81900.00","1.0135"],["81901.90","0.0114"],["81906.40","0.0060"],["81915.10","1280.0673"],["81921.30","0.0124"],["81922.10","488.8000"],["81922.20","0.0157"],["81922.80","12.9402"],["81927.10","0.0061"],["81929.40","0.0059"],["81929.50","0.0081"],["81929.60","0.0058"],["81931.20","0.0150"],["81933.30","0.0007"],["81933.90","0.0025"],["81934.00","0.0032"],["81937.10","611.0025"],["81937.20","0.0030"],["81937.90","0.0020"],["81938.40","0.0010"],["81940.90","0.0030"],["81942.30","0.0036"],["81942.90","0.0015"],["81943.00","0.0033"],["81943.10","0.0012"],["81943.20","0.0031"],["81943.40","0.0015"],["81944.90","0.0288"],["81945.00","0.0276"],["81945.40","0.0016"],["81946.20","488.8018"],["81972.50","0.0334"],["81985.90","0.0020"],["81989.00","0.0007"],["81989.10","474.2653"],["81989.20","35.1598"],["81989.30","35.1541"],["81989.70","70.3082"],["81991.00","35.1541"],["81991.10","35.1541"],["81991.50","0.0214"],["81991.60","35.1541"],["81992.50","35.1541"],["81992.60","70.3082"],["81992.90","35.1541"],["81993.00","35.1541"],["81994.10","35.1541"],["81994.70","35.1541"],["81994.90","0.0036"],["81995.80","35.1541"],["81996.30","35.1541"],["81999.10","0.6116"],["82000.00","621.2141"],["82001.10","35.1541"],["82002.50","35.1541"],["82002.80","70.3082"],["82003.70","0.0052"],["82003.80","0.0322"],["82003.90","0.0087"],["82004.70","0.0608"],["82004.80","0.0331"],["82006.90","0.0822"],["82008.00","0.0085"],["82009.90","27.9337"],["82010.00","233.8821"],["82010.10","114.4274"],["82010.20","97.8970"],["82010.30","29.2533"],["82010.40","146.3043"],["82010.60","12.1981"],["82010.70","29.2533"],["82011.00","29.2533"],["82011.10","78.0214"],["82011.20","70.7047"],["82011.40","12.2007"],["82011.70","29.2533"],["82011.80","48.7681"],["82011.90","12.1981"],["82012.10","53.6495"],["82012.20","41.4514"],["82013.00","29.2550"],["82013.90","12.1981"],["82014.00","0.0019"],["82014.10","60.9662"],["82014.30","29.2533"],["82014.40","12.2021"],["82014.50","0.0029"],["82016.70","12.1981"],["82016.80","29.2533"],["82016.90","0.0049"],["82017.00","61.0029"],["82018.10","0.0008"],["82020.00","1.9945"],["82024.40","0.1800"],["82030.60","0.5000"],["82033.90","0.5000"],["82051.80","3.0468"],["82053.40","0.0560"],["82067.70","5.4489"],["82081.40","4.7420"],["82082.60","54.8202"],["82083.00","0.0017"],["82083.80","54.8202"],["82085.30","60.9124"],["82085.50","54.8209"],["82085.90","0.0120"],["82089.10","60.9124"],["82091.80","0.0035"],["82100.00","0.0118"],["82105.40","0.0012"],["82111.00","1000.0121"],["82130.90","0.0059"],["82150.00","0.5379"],["82175.10","56.7523"],["82175.20","0.0089"],["82175.30","121.6796"],["82175.70","60.8424"],["82175.80","60.8398"],["82177.20","60.8398"],["82177.70","60.8398"],["82178.10","121.6796"],["82178.70","60.8398"],["82178.90","60.8398"],["82179.80","60.8398"],["82180.10","60.8398"],["82181.10","60.8398"],["82182.50","609.0113"],["82182.60","0.0066"],["82182.70","60.8398"],["82185.60","60.8398"],["82185.70","487.2111"],["82185.80","0.0019"],["82186.40","60.8398"],["82193.00","0.0608"],["82195.50","0.0028"],["82198.50","0.0100"],["82200.00","0.1549"],["82212.80","0.0085"],["82222.00","1.0000"],["82222.20","1.0000"],["82236.00","1.2160"],["82239.10","0.0007"],["82245.00","0.2705"],["82258.70","73.6344"],["82260.30","35.8561"],["82260.40","49.0800"],["82260.50","69.2670"],["82260.80","56.9970"],["82261.40","113.9940"],["82261.60","0.0025"],["82262.40","37.9817"],["82262.50","75.9634"],["82262.70","37.9817"],["82262.80","56.9970"],["82262.90","37.9862"],["82263.00","75.9656"],["82263.10","56.9970"],["82263.20","37.9817"],["82263.30","75.9642"],["82263.40","0.0084"],["82263.90","56.9970"],["82264.40","56.9970"],["82264.50","56.9970"],["82265.70","56.9970"],["82266.00","1.0000"],["82267.40","1216.0182"],["82268.20","0.0031"],["82278.00","0.0143"],["82285.70","0.0141"],["82286.80","11.3951"],["82288.50","13.2146"],["82289.50","13.2139"],["82290.30","0.0007"],["82290.70","13.2146"],["82291.00","34.3377"],["82291.20","67.7952"],["82291.30","37.9522"],["82291.40","145.6035"],["82291.50","75.9044"],["82291.60","13.2146"],["82291.70","13.2146"],["82292.10","37.9522"],["82292.40","37.9522"],["82292.50","37.9522"],["82292.70","37.9522"],["82294.20","36.8283"],["82300.00","0.7245"],["82303.90","26.8623"],["82304.00","29.8806"],["82304.30","60.1096"],["82304.40","40.6169"],["82304.50","40.6169"],["82304.80","40.6169"],["82305.20","0.0192"],["82305.30","242.9957"],["82305.60","0.0036"],["82307.90","60.8018"],["82308.30","0.0055"],["82308.40","364.8017"],["82308.50","121.6000"],["82308.80","0.0030"],["82309.60","60.8121"],["82309.70","608.0143"],["82310.30","0.0071"],["82311.20","0.0026"],["82311.60","0.0023"],["82311.70","0.0108"],["82311.80","0.0017"],["82312.00","0.0105"],["82312.10","33.3796"],["82312.40","364.8090"],["82312.50","0.0014"],["82312.70","0.0017"],["82312.80","0.2469"],["82312.90","33.3796"],["82313.10","0.0028"],["82313.20","0.0152"],["82313.70","33.3796"],["82313.80","33.3796"],["82314.30","486.4110"],["82314.40","0.0128"],["82314.90","1033.6118"],["82315.00","0.0038"],["82315.10","33.3812"],["82315.50","33.3796"],["82317.00","33.3796"],["82317.50","60.1096"],["82318.80","547.2046"],["82319.20","0.0007"],["82319.50","0.0028"],["82320.10","0.0034"],["82320.80","0.0026"],["82320.90","0.0144"],["82321.60","33.3796"],["82324.90","547.2021"],["82349.40","0.0118"],["82356.50","0.0007"],["82369.00","0.0921"],["82379.90","318.1342"],["82380.50","43.8911"],["82381.00","43.8911"],["82381.20","0.0008"],["82381.40","43.8911"],["82382.30","0.0051"],["82382.80","43.8911"],["82383.80","30.3400"],["82383.90","30.3400"],["82384.00","303.5000"],["82384.10","333.8400"],["82384.50","43.8911"],["82386.90","60.7000"],["82387.10","60.7000"],["82387.40","121.4000"],["82387.50","182.1000"],["82387.60","121.4000"],["82387.90","102.3438"],["82388.10","43.4880"],["82388.20","49.4661"],["82388.40","32.9774"],["82388.50","54.7214"],["82388.70","82.1238"],["82388.80","38.2327"],["82389.00","43.8911"],["82389.10","21.7440"],["82389.50","0.0075"],["82389.60","607.0079"],["82390.00","0.0109"],["82390.10","0.0084"],["82390.50","43.8911"],["82391.40","0.0009"],["82395.10","0.0023"],["82395.40","10.6114"],["82395.50","43.8911"],["82397.60","0.0039"],["82402.60","0.0033"],["82402.90","607.0032"],["82403.10","60.6767"],["82403.30","60.6767"],["82403.60","60.6767"],["82403.70","0.0044"],["82403.90","0.0030"],["82404.80","60.6767"],["82404.90","121.3534"],["82405.80","60.6767"],["82406.00","60.6767"],["82406.70","60.6767"],["82406.80","121.3534"],["82406.90","60.6767"],["82407.20","60.6767"],["82407.50","60.6767"],["82408.80","60.6767"],["82409.50","0.0011"],["82409.80","60.6767"],["82411.10","60.6767"],["82415.20","0.0020"],["82415.30","0.0031"],["82415.80","60.6767"],["82417.30","60.6767"],["82418.70","60.6767"],["82435.00","0.0020"],["82438.90","1.2000"],["82450.00","0.6064"],["82467.70","0.0012"],["82470.50","0.0012"],["82472.70","0.0012"]]}}
{"schema_version":"glitch.crypto.binance-usdm-stream-evidence.v1","session_id":"ef8dc32d-fcff-4814-9419-b04573c2aaca","sequence":14,"recorded_utc":"2026-08-25T02:48:29.590Z","channel":"public-depth","kind":"transition","payload":{"state":"running","epoch":1,"connection_id":"fc393e01-4a66-488a-8382-876f9e9544ec","update_id":410738888230}}
{"schema_version":"glitch.crypto.binance-usdm-stream-evidence.v2","session_id":"ef8dc32d-fcff-4814-9419-b04573c2aaca","sequence":15,"recorded_utc":"2026-08-25T02:48:30.027Z","channel":"public-depth","kind":"message","payload":{"e":"depthUpdate","E":1787626108550,"T":1787626108411,"s":"BTCUSDT","ps":"BTCUSDT","U":410738892187,"u":410738892187,"pu":410738888230,"b":[["60826.00","0.0200"]],"a":[],"st":1},"provenance":{"venue":"BINANCE_USDM","instrument":"BTCUSDT","channel":"public-depth","connection_id":"fc393e01-4a66-488a-8382-876f9e9544ec","local_receive_timestamp_ms":1787626110027,"monotonic_receive_ns":"4252384699","exchange_timestamp_ms":1787626108550,"provider_sequence":{"event_type":"depthUpdate","event_time_ms":1787626108550,"aggregate_trade_id":null,"first_trade_id":null,"last_trade_id":null,"trade_time_ms":null,"first_update_id":410738892187,"final_update_id":410738892187,"previous_final_update_id":410738888230,"transaction_time_ms":1787626108411},"normalization_version":"binance-usdm-depth-inspection.v1","raw_frame":"{\"e\":\"depthUpdate\",\"E\":1787626108550,\"T\":1787626108411,\"s\":\"BTCUSDT\",\"ps\":\"BTCUSDT\",\"U\":410738892187,\"u\":410738892187,\"pu\":410738888230,\"b\":[[\"60826.00\",\"0.0200\"]],\"a\":[],\"st\":1}","raw_frame_sha256":"6bc16cabb7d175a0934b4192c9c6549fc187c059bca27365be187a2a0c589a3c"}}
{"schema_version":"glitch.crypto.binance-usdm-stream-evidence.v2","session_id":"ef8dc32d-fcff-4814-9419-b04573c2aaca","sequence":16,"recorded_utc":"2026-08-25T02:48:30.504Z","channel":"public-depth","kind":"message","payload":{"e":"depthUpdate","E":1787626109027,"T":1787626108964,"s":"BTCUSDT","ps":"BTCUSDT","U":410738897181,"u":410738897608,"pu":410738892187,"b":[["61831.00","0.0200"],["80164.20","0.0000"]],"a":[],"st":1},"provenance":{"venue":"BINANCE_USDM","instrument":"BTCUSDT","channel":"public-depth","connection_id":"fc393e01-4a66-488a-8382-876f9e9544ec","local_receive_timestamp_ms":1787626110504,"monotonic_receive_ns":"4729617700","exchange_timestamp_ms":1787626109027,"provider_sequence":{"event_type":"depthUpdate","event_time_ms":1787626109027,"aggregate_trade_id":null,"first_trade_id":null,"last_trade_id":null,"trade_time_ms":null,"first_update_id":410738897181,"final_update_id":410738897608,"previous_final_update_id":410738892187,"transaction_time_ms":1787626108964},"normalization_version":"binance-usdm-depth-inspection.v1","raw_frame":"{\"e\":\"depthUpdate\",\"E\":1787626109027,\"T\":1787626108964,\"s\":\"BTCUSDT\",\"ps\":\"BTCUSDT\",\"U\":410738897181,\"u\":410738897608,\"pu\":410738892187,\"b\":[[\"61831.00\",\"0.0200\"],[\"80164.20\",\"0.0000\"]],\"a\":[],\"st\":1}","raw_frame_sha256":"c8d2b7e9e69ce7ba66942f144d7a1073e13d4a0cc1a381cf9d5f5633f922fb15"}}
{"schema_version":"glitch.crypto.binance-usdm-stream-evidence.v2","session_id":"ef8dc32d-fcff-4814-9419-b04573c2aaca","sequence":17,"recorded_utc":"2026-08-25T02:48:30.644Z","channel":"public-depth","kind":"message","payload":{"e":"depthUpdate","E":1787626109157,"T":1787626109151,"s":"BTCUSDT","ps":"BTCUSDT","U":410738898165,"u":410738899392,"pu":410738897608,"b":[["80164.20","0.0049"],["80770.80","0.0018"],["80770.90","0.0022"]],"a":[["81415.70","0.0041"],["81416.30","0.0000"]],"st":1},"provenance":{"venue":"BINANCE_USDM","instrument":"BTCUSDT","channel":"public-depth","connection_id":"fc393e01-4a66-488a-8382-876f9e9544ec","local_receive_timestamp_ms":1787626110644,"monotonic_receive_ns":"4869959500","exchange_timestamp_ms":1787626109157,"provider_sequence":{"event_type":"depthUpdate","event_time_ms":1787626109157,"aggregate_trade_id":null,"first_trade_id":null,"last_trade_id":null,"trade_time_ms":null,"first_update_id":410738898165,"final_update_id":410738899392,"previous_final_update_id":410738897608,"transaction_time_ms":1787626109151},"normalization_version":"binance-usdm-depth-inspection.v1","raw_frame":"{\"e\":\"depthUpdate\",\"E\":1787626109157,\"T\":1787626109151,\"s\":\"BTCUSDT\",\"ps\":\"BTCUSDT\",\"U\":410738898165,\"u\":410738899392,\"pu\":410738897608,\"b\":[[\"80164.20\",\"0.0049\"],[\"80770.80\",\"0.0018\"],[\"80770.90\",\"0.0022\"]],\"a\":[[\"81415.70\",\"0.0041\"],[\"81416.30\",\"0.0000\"]],\"st\":1}","raw_frame_sha256":"04d80ac61c3171e29b7e2130803e12b051aa5aa27dbfc5f4f3b35127123adca9"}}
{"schema_version":"glitch.crypto.binance-usdm-stream-evidence.v2","session_id":"ef8dc32d-fcff-4814-9419-b04573c2aaca","sequence":18,"recorded_utc":"2026-08-25T02:48:30.900Z","channel":"public-depth","kind":"message","payload":{"e":"depthUpdate","E":1787626109415,"T":1787626109367,"s":"BTCUSDT","ps":"BTCUSDT","U":410738900952,"u":410738901390,"pu":410738899392,"b":[["80647.90","0.0000"],["80770.80","0.0028"],["80770.90","0.0012"]],"a":[["80781.80","3.9290"]],"st":1},"provenance":{"venue":"BINANCE_USDM","instrument":"BTCUSDT","channel":"public-depth","connection_id":"fc393e01-4a66-488a-8382-876f9e9544ec","local_receive_timestamp_ms":1787626110900,"monotonic_receive_ns":"5125993500","exchange_timestamp_ms":1787626109415,"provider_sequence":{"event_type":"depthUpdate","event_time_ms":1787626109415,"aggregate_trade_id":null,"first_trade_id":null,"last_trade_id":null,"trade_time_ms":null,"first_update_id":410738900952,"final_update_id":410738901390,"previous_final_update_id":410738899392,"transaction_time_ms":1787626109367},"normalization_version":"binance-usdm-depth-inspection.v1","raw_frame":"{\"e\":\"depthUpdate\",\"E\":1787626109415,\"T\":1787626109367,\"s\":\"BTCUSDT\",\"ps\":\"BTCUSDT\",\"U\":410738900952,\"u\":410738901390,\"pu\":410738899392,\"b\":[[\"80647.90\",\"0.0000\"],[\"80770.80\",\"0.0028\"],[\"80770.90\",\"0.0012\"]],\"a\":[[\"80781.80\",\"3.9290\"]],\"st\":1}","raw_frame_sha256":"37cdbc1bccbc3bb448caea329a2fc7094492154b137e71bbf16183c3acb6499f"}}
{"schema_version":"glitch.crypto.binance-usdm-stream-evidence.v2","session_id":"ef8dc32d-fcff-4814-9419-b04573c2aaca","sequence":19,"recorded_utc":"2026-08-25T02:48:31.020Z","channel":"public-depth","kind":"message","payload":{"e":"depthUpdate","E":1787626109533,"T":1787626109499,"s":"BTCUSDT","ps":"BTCUSDT","U":410738902237,"u":410738903019,"pu":410738901390,"b":[["60100.00","0.0049"],["77068.10","0.0000"],["80642.40","0.0052"]],"a":[["80781.20","0.1271"]],"st":1},"provenance":{"venue":"BINANCE_USDM","instrument":"BTCUSDT","channel":"public-depth","connection_id":"fc393e01-4a66-488a-8382-876f9e9544ec","local_receive_timestamp_ms":1787626111020,"monotonic_receive_ns":"5245598600","exchange_timestamp_ms":1787626109533,"provider_sequence":{"event_type":"depthUpdate","event_time_ms":1787626109533,"aggregate_trade_id":null,"first_trade_id":null,"last_trade_id":null,"trade_time_ms":null,"first_update_id":410738902237,"final_update_id":410738903019,"previous_final_update_id":410738901390,"transaction_time_ms":1787626109499},"normalization_version":"binance-usdm-depth-inspection.v1","raw_frame":"{\"e\":\"depthUpdate\",\"E\":1787626109533,\"T\":1787626109499,\"s\":\"BTCUSDT\",\"ps\":\"BTCUSDT\",\"U\":410738902237,\"u\":410738903019,\"pu\":410738901390,\"b\":[[\"60100.00\",\"0.0049\"],[\"77068.10\",\"0.0000\"],[\"80642.40\",\"0.0052\"]],\"a\":[[\"80781.20\",\"0.1271\"]],\"st\":1}","raw_frame_sha256":"8230c9fd901cc83d5a86b715c04550e4ff712742f791e1e3e6a65ccb9438e68b"}}
{"schema_version":"glitch.crypto.binance-usdm-stream-evidence.v2","session_id":"ef8dc32d-fcff-4814-9419-b04573c2aaca","sequence":20,"recorded_utc":"2026-08-25T02:48:31.147Z","channel":"public-depth","kind":"message","payload":{"e":"depthUpdate","E":1787626109659,"T":1787626109539,"s":"BTCUSDT","ps":"BTCUSDT","U":410738903360,"u":410738903360,"pu":410738903019,"b":[["62836.00","0.0200"]],"a":[],"st":1},"provenance":{"venue":"BINANCE_USDM","instrument":"BTCUSDT","channel":"public-depth","connection_id":"fc393e01-4a66-488a-8382-876f9e9544ec","local_receive_timestamp_ms":1787626111147,"monotonic_receive_ns":"5373056300","exchange_timestamp_ms":1787626109659,"provider_sequence":{"event_type":"depthUpdate","event_time_ms":1787626109659,"aggregate_trade_id":null,"first_trade_id":null,"last_trade_id":null,"trade_time_ms":null,"first_update_id":410738903360,"final_update_id":410738903360,"previous_final_update_id":410738903019,"transaction_time_ms":1787626109539},"normalization_version":"binance-usdm-depth-inspection.v1","raw_frame":"{\"e\":\"depthUpdate\",\"E\":1787626109659,\"T\":1787626109539,\"s\":\"BTCUSDT\",\"ps\":\"BTCUSDT\",\"U\":410738903360,\"u\":410738903360,\"pu\":410738903019,\"b\":[[\"62836.00\",\"0.0200\"]],\"a\":[],\"st\":1}","raw_frame_sha256":"a3eb34af2f0d44c421870ef76ec260cf211ed355b4722c78331d743225e623c8"}}
{"schema_version":"glitch.crypto.binance-usdm-stream-evidence.v2","session_id":"ef8dc32d-fcff-4814-9419-b04573c2aaca","sequence":21,"recorded_utc":"2026-08-25T02:48:31.337Z","channel":"public-depth","kind":"message","payload":{"e":"depthUpdate","E":1787626109859,"T":1787626109747,"s":"BTCUSDT","ps":"BTCUSDT","U":410738905163,"u":410738905163,"pu":410738903360,"b":[["77068.10","0.0500"]],"a":[],"st":1},"provenance":{"venue":"BINANCE_USDM","instrument":"BTCUSDT","channel":"public-depth","connection_id":"fc393e01-4a66-488a-8382-876f9e9544ec","local_receive_timestamp_ms":1787626111337,"monotonic_receive_ns":"5562559600","exchange_timestamp_ms":1787626109859,"provider_sequence":{"event_type":"depthUpdate","event_time_ms":1787626109859,"aggregate_trade_id":null,"first_trade_id":null,"last_trade_id":null,"trade_time_ms":null,"first_update_id":410738905163,"final_update_id":410738905163,"previous_final_update_id":410738903360,"transaction_time_ms":1787626109747},"normalization_version":"binance-usdm-depth-inspection.v1","raw_frame":"{\"e\":\"depthUpdate\",\"E\":1787626109859,\"T\":1787626109747,\"s\":\"BTCUSDT\",\"ps\":\"BTCUSDT\",\"U\":410738905163,\"u\":410738905163,\"pu\":410738903360,\"b\":[[\"77068.10\",\"0.0500\"]],\"a\":[],\"st\":1}","raw_frame_sha256":"6c111d9ad642b9cb480f59ff2363e0510657ba03023bf8cdaa42cbff596b0cb8"}}
{"schema_version":"glitch.crypto.binance-usdm-stream-evidence.v2","session_id":"ef8dc32d-fcff-4814-9419-b04573c2aaca","sequence":22,"recorded_utc":"2026-08-25T02:48:31.689Z","channel":"public-depth","kind":"message","payload":{"e":"depthUpdate","E":1787626110205,"T":1787626110183,"s":"BTCUSDT","ps":"BTCUSDT","U":410738908344,"u":410738909512,"pu":410738905163,"b":[["60826.00","0.0000"],["61831.00","0.0000"],["62836.00","0.0000"],["63841.00","0.0200"],["80770.10","0.0042"]],"a":[],"st":1},"provenance":{"venue":"BINANCE_USDM","instrument":"BTCUSDT","channel":"public-depth","connection_id":"fc393e01-4a66-488a-8382-876f9e9544ec","local_receive_timestamp_ms":1787626111689,"monotonic_receive_ns":"5914238100","exchange_timestamp_ms":1787626110205,"provider_sequence":{"event_type":"depthUpdate","event_time_ms":1787626110205,"aggregate_trade_id":null,"first_trade_id":null,"last_trade_id":null,"trade_time_ms":null,"first_update_id":410738908344,"final_update_id":410738909512,"previous_final_update_id":410738905163,"transaction_time_ms":1787626110183},"normalization_version":"binance-usdm-depth-inspection.v1","raw_frame":"{\"e\":\"depthUpdate\",\"E\":1787626110205,\"T\":1787626110183,\"s\":\"BTCUSDT\",\"ps\":\"BTCUSDT\",\"U\":410738908344,\"u\":410738909512,\"pu\":410738905163,\"b\":[[\"60826.00\",\"0.0000\"],[\"61831.00\",\"0.0000\"],[\"62836.00\",\"0.0000\"],[\"63841.00\",\"0.0200\"],[\"80770.10\",\"0.0042\"]],\"a\":[],\"st\":1}","raw_frame_sha256":"65c23184a8d6302fe65733a2454b4fa35d5e33d18780d50a2ec3b43bff57fff2"}}
{"schema_version":"glitch.crypto.binance-usdm-stream-evidence.v2","session_id":"ef8dc32d-fcff-4814-9419-b04573c2aaca","sequence":23,"recorded_utc":"2026-08-25T02:48:31.993Z","channel":"public-depth","kind":"message","payload":{"e":"depthUpdate","E":1787626110509,"T":1787626110403,"s":"BTCUSDT","ps":"BTCUSDT","U":410738911982,"u":410738911982,"pu":410738909512,"b":[["78525.40","0.0015"],["78551.10","0.0000"]],"a":[],"st":1},"provenance":{"venue":"BINANCE_USDM","instrument":"BTCUSDT","channel":"public-depth","connection_id":"fc393e01-4a66-488a-8382-876f9e9544ec","local_receive_timestamp_ms":1787626111992,"monotonic_receive_ns":"6218116200","exchange_timestamp_ms":1787626110509,"provider_sequence":{"event_type":"depthUpdate","event_time_ms":1787626110509,"aggregate_trade_id":null,"first_trade_id":null,"last_trade_id":null,"trade_time_ms":null,"first_update_id":410738911982,"final_update_id":410738911982,"previous_final_update_id":410738909512,"transaction_time_ms":1787626110403},"normalization_version":"binance-usdm-depth-inspection.v1","raw_frame":"{\"e\":\"depthUpdate\",\"E\":1787626110509,\"T\":1787626110403,\"s\":\"BTCUSDT\",\"ps\":\"BTCUSDT\",\"U\":410738911982,\"u\":410738911982,\"pu\":410738909512,\"b\":[[\"78525.40\",\"0.0015\"],[\"78551.10\",\"0.0000\"]],\"a\":[],\"st\":1}","raw_frame_sha256":"cc0002911e0081d4afb60ed5bb70b72bf4004eab34cc778c82e4067194a649e4"}}
{"schema_version":"glitch.crypto.binance-usdm-stream-evidence.v2","session_id":"ef8dc32d-fcff-4814-9419-b04573c2aaca","sequence":24,"recorded_utc":"2026-08-25T02:48:32.162Z","channel":"public-depth","kind":"message","payload":{"e":"depthUpdate","E":1787626110685,"T":1787626110647,"s":"BTCUSDT","ps":"BTCUSDT","U":410738913664,"u":410738914269,"pu":410738911982,"b":[["74438.20","0.0370"],["76731.50","32.1795"],["76731.60","0.0020"]],"a":[],"st":1},"provenance":{"venue":"BINANCE_USDM","instrument":"BTCUSDT","channel":"public-depth","connection_id":"fc393e01-4a66-488a-8382-876f9e9544ec","local_receive_timestamp_ms":1787626112162,"monotonic_receive_ns":"6387280300","exchange_timestamp_ms":1787626110685,"provider_sequence":{"event_type":"depthUpdate","event_time_ms":1787626110685,"aggregate_trade_id":null,"first_trade_id":null,"last_trade_id":null,"trade_time_ms":null,"first_update_id":410738913664,"final_update_id":410738914269,"previous_final_update_id":410738911982,"transaction_time_ms":1787626110647},"normalization_version":"binance-usdm-depth-inspection.v1","raw_frame":"{\"e\":\"depthUpdate\",\"E\":1787626110685,\"T\":1787626110647,\"s\":\"BTCUSDT\",\"ps\":\"BTCUSDT\",\"U\":410738913664,\"u\":410738914269,\"pu\":410738911982,\"b\":[[\"74438.20\",\"0.0370\"],[\"76731.50\",\"32.1795\"],[\"76731.60\",\"0.0020\"]],\"a\":[],\"st\":1}","raw_frame_sha256":"124fe3295ccf07ef49578b8d2e8cda04ae255fa90884c1756adeb5e221a1b461"}}
{"schema_version":"glitch.crypto.binance-usdm-stream-evidence.v2","session_id":"ef8dc32d-fcff-4814-9419-b04573c2aaca","sequence":25,"recorded_utc":"2026-08-25T02:48:32.309Z","channel":"public-depth","kind":"message","payload":{"e":"depthUpdate","E":1787626110805,"T":1787626110799,"s":"BTCUSDT","ps":"BTCUSDT","U":410738914661,"u":410738915567,"pu":410738914269,"b":[["64846.00","0.0200"],["80640.60","0.0052"],["80642.40","0.0000"]],"a":[],"st":1},"provenance":{"venue":"BINANCE_USDM","instrument":"BTCUSDT","channel":"public-depth","connection_id":"fc393e01-4a66-488a-8382-876f9e9544ec","local_receive_timestamp_ms":1787626112309,"monotonic_receive_ns":"6535063900","exchange_timestamp_ms":1787626110805,"provider_sequence":{"event_type":"depthUpdate","event_time_ms":1787626110805,"aggregate_trade_id":null,"first_trade_id":null,"last_trade_id":null,"trade_time_ms":null,"first_update_id":410738914661,"final_update_id":410738915567,"previous_final_update_id":410738914269,"transaction_time_ms":1787626110799},"normalization_version":"binance-usdm-depth-inspection.v1","raw_frame":"{\"e\":\"depthUpdate\",\"E\":1787626110805,\"T\":1787626110799,\"s\":\"BTCUSDT\",\"ps\":\"BTCUSDT\",\"U\":410738914661,\"u\":410738915567,\"pu\":410738914269,\"b\":[[\"64846.00\",\"0.0200\"],[\"80640.60\",\"0.0052\"],[\"80642.40\",\"0.0000\"]],\"a\":[],\"st\":1}","raw_frame_sha256":"4dca797f1d3cc07ce2b7f02f3c426c56849a4c2da9dbb194a87442e808af30a8"}}
{"schema_version":"glitch.crypto.binance-usdm-stream-evidence.v2","session_id":"ef8dc32d-fcff-4814-9419-b04573c2aaca","sequence":26,"recorded_utc":"2026-08-25T02:48:32.551Z","channel":"public-depth","kind":"message","payload":{"e":"depthUpdate","E":1787626111061,"T":1787626110935,"s":"BTCUSDT","ps":"BTCUSDT","U":410738917027,"u":410738917027,"pu":410738915567,"b":[["80164.20","0.0000"]],"a":[],"st":1},"provenance":{"venue":"BINANCE_USDM","instrument":"BTCUSDT","channel":"public-depth","connection_id":"fc393e01-4a66-488a-8382-876f9e9544ec","local_receive_timestamp_ms":1787626112551,"monotonic_receive_ns":"6776647400","exchange_timestamp_ms":1787626111061,"provider_sequence":{"event_type":"depthUpdate","event_time_ms":1787626111061,"aggregate_trade_id":null,"first_trade_id":null,"last_trade_id":null,"trade_time_ms":null,"first_update_id":410738917027,"final_update_id":410738917027,"previous_final_update_id":410738915567,"transaction_time_ms":1787626110935},"normalization_version":"binance-usdm-depth-inspection.v1","raw_frame":"{\"e\":\"depthUpdate\",\"E\":1787626111061,\"T\":1787626110935,\"s\":\"BTCUSDT\",\"ps\":\"BTCUSDT\",\"U\":410738917027,\"u\":410738917027,\"pu\":410738915567,\"b\":[[\"80164.20\",\"0.0000\"]],\"a\":[],\"st\":1}","raw_frame_sha256":"c3e404bf59eb498e6876eed6af6034b5d5ae77b2d6e96e80f26191fa9d08692f"}}
{"schema_version":"glitch.crypto.binance-usdm-stream-evidence.v2","session_id":"ef8dc32d-fcff-4814-9419-b04573c2aaca","sequence":27,"recorded_utc":"2026-08-25T02:48:32.726Z","channel":"public-depth","kind":"message","payload":{"e":"depthUpdate","E":1787626111243,"T":1787626111120,"s":"BTCUSDT","ps":"BTCUSDT","U":410738918622,"u":410738918715,"pu":410738917027,"b":[["75731.00","0.0370"],["80174.40","0.0049"]],"a":[],"st":1},"provenance":{"venue":"BINANCE_USDM","instrument":"BTCUSDT","channel":"public-depth","connection_id":"fc393e01-4a66-488a-8382-876f9e9544ec","local_receive_timestamp_ms":1787626112726,"monotonic_receive_ns":"6951304000","exchange_timestamp_ms":1787626111243,"provider_sequence":{"event_type":"depthUpdate","event_time_ms":1787626111243,"aggregate_trade_id":null,"first_trade_id":null,"last_trade_id":null,"trade_time_ms":null,"first_update_id":410738918622,"final_update_id":410738918715,"previous_final_update_id":410738917027,"transaction_time_ms":1787626111120},"normalization_version":"binance-usdm-depth-inspection.v1","raw_frame":"{\"e\":\"depthUpdate\",\"E\":1787626111243,\"T\":1787626111120,\"s\":\"BTCUSDT\",\"ps\":\"BTCUSDT\",\"U\":410738918622,\"u\":410738918715,\"pu\":410738917027,\"b\":[[\"75731.00\",\"0.0370\"],[\"80174.40\",\"0.0049\"]],\"a\":[],\"st\":1}","raw_frame_sha256":"f5fa7dcf4730453c42fcb24aaaf3c8a7b7613d8fe301c888e1753d72afc2b2c0"}}
{"schema_version":"glitch.crypto.binance-usdm-stream-evidence.v2","session_id":"ef8dc32d-fcff-4814-9419-b04573c2aaca","sequence":28,"recorded_utc":"2026-08-25T02:48:33.041Z","channel":"public-depth","kind":"message","payload":{"e":"depthUpdate","E":1787626111555,"T":1787626111457,"s":"BTCUSDT","ps":"BTCUSDT","U":410738921581,"u":410738922008,"pu":410738918715,"b":[["80770.00","27.1183"],["80770.10","0.0000"],["80770.80","0.0009"],["80770.90","0.0000"]],"a":[["80781.20","0.1313"]],"st":1},"provenance":{"venue":"BINANCE_USDM","instrument":"BTCUSDT","channel":"public-depth","connection_id":"fc393e01-4a66-488a-8382-876f9e9544ec","local_receive_timestamp_ms":1787626113041,"monotonic_receive_ns":"7266619500","exchange_timestamp_ms":1787626111555,"provider_sequence":{"event_type":"depthUpdate","event_time_ms":1787626111555,"aggregate_trade_id":null,"first_trade_id":null,"last_trade_id":null,"trade_time_ms":null,"first_update_id":410738921581,"final_update_id":410738922008,"previous_final_update_id":410738918715,"transaction_time_ms":1787626111457},"normalization_version":"binance-usdm-depth-inspection.v1","raw_frame":"{\"e\":\"depthUpdate\",\"E\":1787626111555,\"T\":1787626111457,\"s\":\"BTCUSDT\",\"ps\":\"BTCUSDT\",\"U\":410738921581,\"u\":410738922008,\"pu\":410738918715,\"b\":[[\"80770.00\",\"27.1183\"],[\"80770.10\",\"0.0000\"],[\"80770.80\",\"0.0009\"],[\"80770.90\",\"0.0000\"]],\"a\":[[\"80781.20\",\"0.1313\"]],\"st\":1}","raw_frame_sha256":"4befc96807655fc7109ebd8a094f3aab717f959fdb296bd139bb34109e55560b"}}
{"schema_version":"glitch.crypto.binance-usdm-stream-evidence.v2","session_id":"ef8dc32d-fcff-4814-9419-b04573c2aaca","sequence":29,"recorded_utc":"2026-08-25T02:48:33.144Z","channel":"public-depth","kind":"message","payload":{"e":"depthUpdate","E":1787626111667,"T":1787626111652,"s":"BTCUSDT","ps":"BTCUSDT","U":410738922661,"u":410738923827,"pu":410738922008,"b":[["80640.60","0.0000"],["80770.80","0.0014"]],"a":[],"st":1},"provenance":{"venue":"BINANCE_USDM","instrument":"BTCUSDT","channel":"public-depth","connection_id":"fc393e01-4a66-488a-8382-876f9e9544ec","local_receive_timestamp_ms":1787626113144,"monotonic_receive_ns":"7369332800","exchange_timestamp_ms":1787626111667,"provider_sequence":{"event_type":"depthUpdate","event_time_ms":1787626111667,"aggregate_trade_id":null,"first_trade_id":null,"last_trade_id":null,"trade_time_ms":null,"first_update_id":410738922661,"final_update_id":410738923827,"previous_final_update_id":410738922008,"transaction_time_ms":1787626111652},"normalization_version":"binance-usdm-depth-inspection.v1","raw_frame":"{\"e\":\"depthUpdate\",\"E\":1787626111667,\"T\":1787626111652,\"s\":\"BTCUSDT\",\"ps\":\"BTCUSDT\",\"U\":410738922661,\"u\":410738923827,\"pu\":410738922008,\"b\":[[\"80640.60\",\"0.0000\"],[\"80770.80\",\"0.0014\"]],\"a\":[],\"st\":1}","raw_frame_sha256":"bab4e217814d02783ffdfc6d99ea85d43800a661da217461ed4e31c9214d7d47"}}
{"schema_version":"glitch.crypto.binance-usdm-stream-evidence.v2","session_id":"ef8dc32d-fcff-4814-9419-b04573c2aaca","sequence":30,"recorded_utc":"2026-08-25T02:48:33.282Z","channel":"public-depth","kind":"message","payload":{"e":"depthUpdate","E":1787626111801,"T":1787626111720,"s":"BTCUSDT","ps":"BTCUSDT","U":410738924152,"u":410738924518,"pu":410738923827,"b":[["80644.30","0.0052"],["80770.80","0.0000"]],"a":[],"st":1},"provenance":{"venue":"BINANCE_USDM","instrument":"BTCUSDT","channel":"public-depth","connection_id":"fc393e01-4a66-488a-8382-876f9e9544ec","local_receive_timestamp_ms":1787626113282,"monotonic_receive_ns":"7507393600","exchange_timestamp_ms":1787626111801,"provider_sequence":{"event_type":"depthUpdate","event_time_ms":1787626111801,"aggregate_trade_id":null,"first_trade_id":null,"last_trade_id":null,"trade_time_ms":null,"first_update_id":410738924152,"final_update_id":410738924518,"previous_final_update_id":410738923827,"transaction_time_ms":1787626111720},"normalization_version":"binance-usdm-depth-inspection.v1","raw_frame":"{\"e\":\"depthUpdate\",\"E\":1787626111801,\"T\":1787626111720,\"s\":\"BTCUSDT\",\"ps\":\"BTCUSDT\",\"U\":410738924152,\"u\":410738924518,\"pu\":410738923827,\"b\":[[\"80644.30\",\"0.0052\"],[\"80770.80\",\"0.0000\"]],\"a\":[],\"st\":1}","raw_frame_sha256":"61b0400f9b31a30263cea042415a5ba3e620aa28c3770a257aa59cc914e4f7bf"}}
{"schema_version":"glitch.crypto.binance-usdm-stream-evidence.v2","session_id":"ef8dc32d-fcff-4814-9419-b04573c2aaca","sequence":31,"recorded_utc":"2026-08-25T02:48:33.494Z","channel":"public-depth","kind":"message","payload":{"e":"depthUpdate","E":1787626112005,"T":1787626111975,"s":"BTCUSDT","ps":"BTCUSDT","U":410738925704,"u":410738926857,"pu":410738924518,"b":[["40390.60","0.0015"],["80770.00","27.1163"]],"a":[],"st":1},"provenance":{"venue":"BINANCE_USDM","instrument":"BTCUSDT","channel":"public-depth","connection_id":"fc393e01-4a66-488a-8382-876f9e9544ec","local_receive_timestamp_ms":1787626113494,"monotonic_receive_ns":"7719896200","exchange_timestamp_ms":1787626112005,"provider_sequence":{"event_type":"depthUpdate","event_time_ms":1787626112005,"aggregate_trade_id":null,"first_trade_id":null,"last_trade_id":null,"trade_time_ms":null,"first_update_id":410738925704,"final_update_id":410738926857,"previous_final_update_id":410738924518,"transaction_time_ms":1787626111975},"normalization_version":"binance-usdm-depth-inspection.v1","raw_frame":"{\"e\":\"depthUpdate\",\"E\":1787626112005,\"T\":1787626111975,\"s\":\"BTCUSDT\",\"ps\":\"BTCUSDT\",\"U\":410738925704,\"u\":410738926857,\"pu\":410738924518,\"b\":[[\"40390.60\",\"0.0015\"],[\"80770.00\",\"27.1163\"]],\"a\":[],\"st\":1}","raw_frame_sha256":"3f5a2e75c8941203f0f28d05a57508c684993c1e864d7a82a8d573328797485b"}}
{"schema_version":"glitch.crypto.binance-usdm-stream-evidence.v2","session_id":"ef8dc32d-fcff-4814-9419-b04573c2aaca","sequence":32,"recorded_utc":"2026-08-25T02:48:33.894Z","channel":"public-depth","kind":"message","payload":{"e":"depthUpdate","E":1787626112417,"T":1787626112351,"s":"BTCUSDT","ps":"BTCUSDT","U":410738929921,"u":410738930139,"pu":410738926857,"b":[["80763.80","0.0007"],["80770.00","27.1156"]],"a":[],"st":1},"provenance":{"venue":"BINANCE_USDM","instrument":"BTCUSDT","channel":"public-depth","connection_id":"fc393e01-4a66-488a-8382-876f9e9544ec","local_receive_timestamp_ms":1787626113894,"monotonic_receive_ns":"8119881900","exchange_timestamp_ms":1787626112417,"provider_sequence":{"event_type":"depthUpdate","event_time_ms":1787626112417,"aggregate_trade_id":null,"first_trade_id":null,"last_trade_id":null,"trade_time_ms":null,"first_update_id":410738929921,"final_update_id":410738930139,"previous_final_update_id":410738926857,"transaction_time_ms":1787626112351},"normalization_version":"binance-usdm-depth-inspection.v1","raw_frame":"{\"e\":\"depthUpdate\",\"E\":1787626112417,\"T\":1787626112351,\"s\":\"BTCUSDT\",\"ps\":\"BTCUSDT\",\"U\":410738929921,\"u\":410738930139,\"pu\":410738926857,\"b\":[[\"80763.80\",\"0.0007\"],[\"80770.00\",\"27.1156\"]],\"a\":[],\"st\":1}","raw_frame_sha256":"d5f6400637454a670ba10d62899c6205623cc30015da2d2278cbe8576b219b40"}}
{"schema_version":"glitch.crypto.binance-usdm-stream-evidence.v1","session_id":"ef8dc32d-fcff-4814-9419-b04573c2aaca","sequence":33,"recorded_utc":"2026-08-25T02:48:33.950Z","channel":"public-depth","kind":"transition","payload":{"state":"stopped","epoch":2}}
{"schema_version":"glitch.crypto.binance-usdm-stream-evidence.v1","session_id":"ef8dc32d-fcff-4814-9419-b04573c2aaca","sequence":34,"recorded_utc":"2026-08-25T02:48:33.951Z","channel":"supervisor","kind":"transition","payload":{"action":"stop","symbol":"BTCUSDT"}}
