{"schema_version":"glitch.crypto.binance-usdm-stream-evidence.v1","session_id":"96a1bfda-0aa9-43e8-aef7-ef959f56617c","sequence":1,"recorded_utc":"2026-08-24T23:16:53.913Z","channel":"supervisor","kind":"transition","payload":{"action":"start","symbol":"BTCUSDT","private_enabled":false,"mutation_authority":false}}
{"schema_version":"glitch.crypto.binance-usdm-stream-evidence.v1","session_id":"96a1bfda-0aa9-43e8-aef7-ef959f56617c","sequence":2,"recorded_utc":"2026-08-24T23:16:53.948Z","channel":"public-depth","kind":"transition","payload":{"state":"connecting","epoch":1,"stream":"btcusdt@depth@100ms"}}
{"schema_version":"glitch.crypto.binance-usdm-stream-evidence.v1","session_id":"96a1bfda-0aa9-43e8-aef7-ef959f56617c","sequence":3,"recorded_utc":"2026-08-24T23:16:54.502Z","channel":"public-depth","kind":"transition","payload":{"state":"synchronizing","epoch":1}}
{"schema_version":"glitch.crypto.binance-usdm-stream-evidence.v1","session_id":"96a1bfda-0aa9-43e8-aef7-ef959f56617c","sequence":4,"recorded_utc":"2026-08-24T23:16:54.869Z","channel":"public-depth","kind":"snapshot","payload":{"lastUpdateId":410623232396,"bids":[["78688.20","0.0129"],["78688.10","60.5560"],["78688.00","64.0177"],["78687.90","50.6782"],["78687.70","64.3997"],["78687.60","193.4812"],["78687.50","115.7012"],["78687.40","128.1708"],["78687.30","166.9813"],["78687.20","642.3668"],["78687.10","642.4591"],["78687.00","0.0083"],["78685.70","58.1876"],["78685.60","58.6997"],["78685.50","113.0922"],["78685.40","58.2428"],["78685.30","112.5735"],["78685.20","117.6800"],["78685.10","54.0435"],["78684.90","54.1711"]],"asks":[["78706.20","0.0031"],["78719.80","1271.9988"],["78722.80","0.0007"],["78724.30","0.0033"],["78724.90","0.0015"],["78725.60","636.0045"],["78725.70","636.0152"],["78727.70","0.0015"],["78730.10","0.0032"],["78730.20","0.0015"],["78733.60","381.6203"],["78735.30","0.0064"],["78735.40","381.6095"],["78740.60","0.0009"],["78740.70","381.0117"],["78741.10","0.0042"],["78741.20","381.0186"],["78752.50","0.0019"],["78774.80","0.3789"],["78774.90","101.5604"]]}}
{"schema_version":"glitch.crypto.binance-usdm-stream-evidence.v1","session_id":"96a1bfda-0aa9-43e8-aef7-ef959f56617c","sequence":5,"recorded_utc":"2026-08-24T23:16:54.874Z","channel":"public-depth","kind":"transition","payload":{"state":"running","epoch":1,"update_id":410623232396}}
{"schema_version":"glitch.crypto.binance-usdm-stream-evidence.v1","session_id":"96a1bfda-0aa9-43e8-aef7-ef959f56617c","sequence":6,"recorded_utc":"2026-08-24T23:16:55.054Z","channel":"public-depth","kind":"message","payload":{"e":"depthUpdate","E":1787613414985,"T":1787613414851,"s":"BTCUSDT","ps":"BTCUSDT","U":410623235935,"u":410623235935,"pu":410623232396,"b":[["74753.90","0.0020"]],"a":[],"st":1}}
{"schema_version":"glitch.crypto.binance-usdm-stream-evidence.v1","session_id":"96a1bfda-0aa9-43e8-aef7-ef959f56617c","sequence":7,"recorded_utc":"2026-08-24T23:16:55.286Z","channel":"public-depth","kind":"message","payload":{"e":"depthUpdate","E":1787613415225,"T":1787613415091,"s":"BTCUSDT","ps":"BTCUSDT","U":410623238319,"u":410623238319,"pu":410623235935,"b":[["78652.40","0.0000"]],"a":[["78706.20","0.0000"]],"st":1}}
{"schema_version":"glitch.crypto.binance-usdm-stream-evidence.v1","session_id":"96a1bfda-0aa9-43e8-aef7-ef959f56617c","sequence":8,"recorded_utc":"2026-08-24T23:16:55.668Z","channel":"public-depth","kind":"message","payload":{"e":"depthUpdate","E":1787613415607,"T":1787613415467,"s":"BTCUSDT","ps":"BTCUSDT","U":410623241382,"u":410623241382,"pu":410623238319,"b":[["78664.40","0.0063"]],"a":[],"st":1}}
{"schema_version":"glitch.crypto.binance-usdm-stream-evidence.v1","session_id":"96a1bfda-0aa9-43e8-aef7-ef959f56617c","sequence":9,"recorded_utc":"2026-08-24T23:16:55.802Z","channel":"public-depth","kind":"message","payload":{"e":"depthUpdate","E":1787613415741,"T":1787613415679,"s":"BTCUSDT","ps":"BTCUSDT","U":410623242281,"u":410623242956,"pu":410623241382,"b":[["60000.00","19.7858"],["60100.00","0.0059"],["74438.20","0.0440"]],"a":[["78718.20","0.0054"]],"st":1}}
{"schema_version":"glitch.crypto.binance-usdm-stream-evidence.v1","session_id":"96a1bfda-0aa9-43e8-aef7-ef959f56617c","sequence":10,"recorded_utc":"2026-08-24T23:16:55.959Z","channel":"public-depth","kind":"message","payload":{"e":"depthUpdate","E":1787613415899,"T":1787613415823,"s":"BTCUSDT","ps":"BTCUSDT","U":410623243614,"u":410623244109,"pu":410623242956,"b":[["39359.90","0.0016"]],"a":[["78734.70","0.0009"]],"st":1}}
{"schema_version":"glitch.crypto.binance-usdm-stream-evidence.v1","session_id":"96a1bfda-0aa9-43e8-aef7-ef959f56617c","sequence":11,"recorded_utc":"2026-08-24T23:16:56.141Z","channel":"public-depth","kind":"message","payload":{"e":"depthUpdate","E":1787613416079,"T":1787613416031,"s":"BTCUSDT","ps":"BTCUSDT","U":410623245269,"u":410623245884,"pu":410623244109,"b":[],"a":[["78718.20","0.0040"],["78734.70","0.0023"]],"st":1}}
{"schema_version":"glitch.crypto.binance-usdm-stream-evidence.v1","session_id":"96a1bfda-0aa9-43e8-aef7-ef959f56617c","sequence":12,"recorded_utc":"2026-08-24T23:16:56.336Z","channel":"public-depth","kind":"message","payload":{"e":"depthUpdate","E":1787613416275,"T":1787613416215,"s":"BTCUSDT","ps":"BTCUSDT","U":410623246863,"u":410623247573,"pu":410623245884,"b":[["75731.00","0.0440"]],"a":[["78718.20","0.0030"],["78734.70","0.0033"]],"st":1}}
{"schema_version":"glitch.crypto.binance-usdm-stream-evidence.v1","session_id":"96a1bfda-0aa9-43e8-aef7-ef959f56617c","sequence":13,"recorded_utc":"2026-08-24T23:16:56.663Z","channel":"public-depth","kind":"message","payload":{"e":"depthUpdate","E":1787613416603,"T":1787613416543,"s":"BTCUSDT","ps":"BTCUSDT","U":410623249456,"u":410623250174,"pu":410623247573,"b":[["77023.70","0.0440"],["78706.20","0.1409"]],"a":[],"st":1}}
{"schema_version":"glitch.crypto.binance-usdm-stream-evidence.v1","session_id":"96a1bfda-0aa9-43e8-aef7-ef959f56617c","sequence":14,"recorded_utc":"2026-08-24T23:16:56.796Z","channel":"public-depth","kind":"message","payload":{"e":"depthUpdate","E":1787613416735,"T":1787613416615,"s":"BTCUSDT","ps":"BTCUSDT","U":410623250619,"u":410623250619,"pu":410623250174,"b":[["39344.80","0.0000"]],"a":[],"st":1}}
{"schema_version":"glitch.crypto.binance-usdm-stream-evidence.v1","session_id":"96a1bfda-0aa9-43e8-aef7-ef959f56617c","sequence":15,"recorded_utc":"2026-08-24T23:16:57.362Z","channel":"public-depth","kind":"message","payload":{"e":"depthUpdate","E":1787613417295,"T":1787613417207,"s":"BTCUSDT","ps":"BTCUSDT","U":410623255434,"u":410623256294,"pu":410623250619,"b":[],"a":[["78718.20","0.0000"],["78719.80","1271.9768"]],"st":1}}
{"schema_version":"glitch.crypto.binance-usdm-stream-evidence.v1","session_id":"96a1bfda-0aa9-43e8-aef7-ef959f56617c","sequence":16,"recored_utc":"2026-08-24T23:16:57.633Z","channel":"public-depth","kind":"message","payload":{"e":"depthUpdate","E":1787613417573,"T":1787613417527,"s":"BTCUSDT","ps":"BTCUSDT","U":410623258542,"u":410623259554,"pu":410623256294,"b":[["78706.20","0.1397"]],"a":[["78719.80","1271.9778"],["79609.20","0.0440"]],"st":1}}
{"schema_version":"glitch.crypto.binance-usdm-stream-evidence.v1","session_id":"96a1bfda-0aa9-43e8-aef7-ef959f56617c","sequence":17,"recorded_utc":"2026-08-24T23:16:57.761Z","channel":"public-depth","kind":"message","payload":{"e":"depthUpdate","E":1787613417701,"T":1787613417647,"s":"BTCUSDT","ps":"BTCUSDT","U":410623259829,"u":410623260867,"pu":410623259554,"b":[["60100.00","0.0049"],["78706.20","0.1387"]],"a":[["78719.80","1271.9766"],["78734.60","0.0012"]],"st":1}}
{"schema_version":"glitch.crypto.binance-usdm-stream-evidence.v1","session_id":"96a1bfda-0aa9-43e8-aef7-ef959f56617c","sequence":18,"recorded_utc":"2026-08-24T23:16:58.021Z","channel":"public-depth","kind":"message","payload":{"e":"depthUpdate","E":1787613417959,"T":1787613417851,"s":"BTCUSDT","ps":"BTCUSDT","U":410623262569,"u":410623262587,"pu":410623260867,"b":[["78664.40","0.0000"]],"a":[["78719.80","1271.9756"]],"st":1}}
{"schema_version":"glitch.crypto.binance-usdm-stream-evidence.v1","session_id":"96a1bfda-0aa9-43e8-aef7-ef959f56617c","sequence":19,"recorded_utc":"2026-08-24T23:16:58.134Z","channel":"public-depth","kind":"message","payload":{"e":"depthUpdate","E":1787613418069,"T":1787613417935,"s":"BTCUSDT","ps":"BTCUSDT","U":410623263382,"u":410623263382,"pu":410623262587,"b":[],"a":[["80901.90","0.0440"]],"st":1}}
{"schema_version":"glitch.crypto.binance-usdm-stream-evidence.v1","session_id":"96a1bfda-0aa9-43e8-aef7-ef959f56617c","sequence":20,"recored_utc":"2026-08-24T23:16:58.377Z","channel":"public-depth","kind":"message","payload":{"e":"depthUpdate","E":1787613418317,"T":1787613418235,"s":"BTCUSDT","ps":"BTCUSDT","U":410623266325,"u":410623266728,"pu":410623263382,"b":[["78670.40","0.0063"]],"a":[["78719.80","1271.9746"]],"st":1}}
{"schema_version":"glitch.crypto.binance-usdm-stream-evidence.v1","session_id":"96a1bfda-0aa9-43e8-aef7-ef959f56617c","sequence":21,"recorded_utc":"2026-08-24T23:16:58.508Z","channel":"public-depth","kind":"message","payload":{"e":"depthUpdate","E":1787613418437,"T":1787613418384,"s":"BTCUSDT","ps":"BTCUSDT","U":410623267576,"u":410623268737,"pu":410623266728,"b":[],"a":[["78724.20","0.0063"],["78734.70","0.0043"]],"st":1}}
{"schema_version":"glitch.crypto.binance-usdm-stream-evidence.v1","session_id":"96a1bfda-0aa9-43e8-aef7-ef959f56617c","sequence":22,"recorded_utc":"2026-08-24T23:16:58.875Z","channel":"public-depth","kind":"message","payload":{"e":"depthUpdate","E":1787613418815,"T":1787613418775,"s":"BTCUSDT","ps":"BTCUSDT","U":410623271840,"u":410623272467,"pu":410623268737,"b":[],"a":[["78719.80","1271.9731"],["78734.70","0.0058"]],"st":1}}
{"schema_version":"glitch.crypto.binance-usdm-stream-evidence.v1","session_id":"96a1bfda-0aa9-43e8-aef7-ef959f56617c","sequence":23,"recorded_utc":"2026-08-24T23:16:59.397Z","channel":"public-depth","kind":"message","payload":{"e":"depthUpdate","E":1787613419331,"T":1787613419211,"s":"BTCUSDT","ps":"BTCUSDT","U":410623276279,"u":410623276279,"pu":410623272467,"b":[["74753.90","0.0000"]],"a":[],"st":1}}
{"schema_version":"glitch.crypto.binance-usdm-stream-evidence.v1","session_id":"96a1bfda-0aa9-43e8-aef7-ef959f56617c","sequence":24,"recorded_utc":"2026-08-24T23:17:00.057Z","channel":"public-depth","kind":"message","payload":{"e":"depthUpdate","E":1787613419997,"T":1787613419852,"s":"BTCUSDT","ps":"BTCUSDT","U":410623282471,"u":410623282471,"pu":410623276279,"b":[["78670.40","0.0000"]],"a":[["78724.20","0.0000"]],"st":1}}
{"schema_version":"glitch.crypto.binance-usdm-stream-evidence.v1","session_id":"96a1bfda-0aa9-43e8-aef7-ef959f56617c","sequence":25,"recored_utc":"2026-08-24T23:17:00.203Z","channel":"public-depth","kind":"message","payload":{"e":"depthUpdate","E":1787613420143,"T":1787613420067,"s":"BTCUSDT","ps":"BTCUSDT","U":410623283752,"u":410623284362,"pu":410623282471,"b":[["78683.60","0.0063"],["78688.20","0.0666"],["78706.20","0.1261"]],"a":[["78719.70","0.0032"],["78719.80","1271.9718"]],"st":1}}
{"schema_version":"glitch.crypto.binance-usdm-stream-evidence.v1","session_id":"96a1bfda-0aa9-43e8-aef7-ef959f56617c","sequence":26,"recorded_utc":"2026-08-24T23:17:00.340Z","channel":"public-depth","kind":"message","payload":{"e":"depthUpdate","E":1787613420279,"T":1787613420247,"s":"BTCUSDT","ps":"BTCUSDT","U":410623284873,"u":410623285657,"pu":410623284362,"b":[],"a":[["78734.70","0.0071"],["78737.40","0.0063"]],"st":1}}
{"schema_version":"glitch.crypto.binance-usdm-stream-evidence.v1","session_id":"96a1bfda-0aa9-43e8-aef7-ef959f56617c","sequence":27,"recorded_utc":"2026-08-24T23:17:00.446Z","channel":"public-depth","kind":"message","payload":{"e":"depthUpdate","E":1787613420385,"T":1787613420343,"s":"BTCUSDT","ps":"BTCUSDT","U":410623285893,"u":410623286530,"pu":410623285657,"b":[["78688.20","0.0679"]],"a":[["78719.70","0.0019"],["78734.70","0.0084"]],"st":1}}
{"schema_version":"glitch.crypto.binance-usdm-stream-evidence.v1","session_id":"96a1bfda-0aa9-43e8-aef7-ef959f56617c","sequence":28,"recorded_utc":"2026-08-24T23:17:01.794Z","channel":"public-depth","kind":"message","payload":{"e":"depthUpdate","E":1787613421723,"T":1787613421583,"s":"BTCUSDT","ps":"BTCUSDT","U":410623296352,"u":410623296352,"pu":410623286530,"b":[["74770.90","0.0020"]],"a":[],"st":1}}
{"schema_version":"glitch.crypto.binance-usdm-stream-evidence.v1","session_id":"96a1bfda-0aa9-43e8-aef7-ef959f56617c","sequence":29,"recorded_utc":"2026-08-24T23:17:01.897Z","channel":"public-depth","kind":"message","payload":{"e":"depthUpdate","E":1787613421837,"T":1787613421807,"s":"BTCUSDT","ps":"BTCUSDT","U":410623297446,"u":410623298091,"pu":410623296352,"b":[["78688.20","0.0698"]],"a":[["78719.70","0.0000"],["78719.80","1271.9674"]],"st":1}}
{"schema_version":"glitch.crypto.binance-usdm-stream-evidence.v1","session_id":"96a1bfda-0aa9-43e8-aef7-ef959f56617c","sequence":30,"recorded_utc":"2026-08-24T23:17:02.076Z","channel":"public-depth","kind":"message","payload":{"e":"depthUpdate","E":1787613421999,"T":1787613421867,"s":"BTCUSDT","ps":"BTCUSDT","U":410623298335,"u":410623298335,"pu":410623298091,"b":[["78683.60","0.0000"]],"a":[["78737.40","0.0000"]],"st":1}}
{"schema_version":"glitch.crypto.binance-usdm-stream-evidence.v1","session_id":"96a1bfda-0aa9-43e8-aef7-ef959f56617c","sequence":31,"recorded_utc":"2026-08-24T23:17:23.950Z","channel":"public-depth","kind":"transition","payload":{"state":"stopped","epoch":2}}
{"schema_version":"glitch.crypto.binance-usdm-stream-evidence.v1","session_id":"96a1bfda-0aa9-43e8-aef7-ef959f56617c","sequence":32,"recorded_utc":"2026-08-24T23:17:23.950Z","channel":"supervisor","kind":"transition","payload":{"action":"stop","symbol":"BTCUSDT"}}
